Workbook

Sheet Main Sheet
A1: Updated Job Spreadsheet
A2: Job Number | B2: Job Name | C2: Job Owner | D2: Contract Signed & Returned. Retention % loaded correctly into Katipolt | E2: Warranty Signed & Returned | F2: Construction Programme Received | G2: Into Work Calculator 2 Weekly | H2: Temp Application Done | I2: Mains Connection Application | J2: POs Sent to Sub contractors | K2: Switchboard Drawing Sent for Approval | L2: Email Sent to QS/Builder to Confirm Order Gear | M2: Long Lead Time Materials Ordered | O2: Client Walk Through | P2: Pre Job Meeting Completed with Staff Job Pack Made | Q2: O&M Manual underway (notes for what's needed) | R2: QA Completed By Others | T2: Job Completion Paperwork Completed | U2: All V.Os captured | W2: Last toolbox date
M3: Ordered | N3: Lead Times Comm. | R3: 1st Fix | S3: 2nd Fix
A4: 7658 | B4: Charity Hospital | C4: Cameron | D4: Yes | F4: Yes | G4: Yes | H4: N/A | I4: N/A | J4: Yes | K4: Yes | L4: Yes | M4: Yes | P4: Yes
A6: 8142 | B6: Fisher Developements | C6: Cameron | D6: Yes | F6: Yes | G6: yes | H6: Yes | I6: Yes | J6: Yes | K6: Yes | M6: Yes
A8: 8824 | B8: 3 Innovation Road | C8: Cameron | F8: Yes | G8: N/A | H8: N/A | I8: Yes | J8: Yes | K8: Yes | L8: Yes | M8: N/A | N8: N/A | O8: Yes | Q8: Yes | R8: Yes | S8: Yes | U8: Yes
A10: 8127 | B10: Rolly Autowash | C10: Cameron | D10: Yes | F10: Yes | G10: No | H10: Yes | I10: Yes | J10: N/A | K10: Yes | M10: Yes
A12: 8183 | B12: Murney - 1 Freight Drive + 109 Iport | C12: Cameron | D12: Yes | F12: Yes | G12: Yes | H12: Yes | I12: Yes | J12: Yes | K12: Yes | L12: Yes | M12: Yes | O12: Yes | P12: Yes | Q12: Yes | R12: Yes | S12: Yes | U12: Yes
A14: 8886 | B14: Monkey Toe - Fisher fit out | C14: Cameron | F14: Yes | G14: No | H14: N/A | I14: Yes | J14: Yes | K14: Yes
A16: 8887 | B16: Tenancy 2 - Fisher Fit out | C16: Cameron | F16: Yes | G16: No | H16: N/A | I16: Yes | J16: Yes | K16: Yes
A18: 8670 | B18: Studio DB - tautara fit out | C18: Cameron | D18: Yes
A20: 8907 | B20: 35 Mania | C20: Cameron | D20: Yes
A22: 9065 | B22: Cooltranz stage 4 | C22: Cameron | D22: Yes | F22: Yes | G22: Yes | H22: N/A | I22: Yes | J22: Yes | K22: Yes | L22: Yes | M22: Yes | N22: Yes | Q22: Yes | R22: Yes | S22: N/A | U22: Yes
A24: 9259 | B24: Andrew Reeve Stage 2 | C24: Cameron | D24: Yes | F24: Yes | G24: Yes | H24: N/A | I24: Yes | J24: Yes | K24: Yes | L24: Yes | M24: Yes | N24: Yes | O24: Yes | P24: Yes | Q24: Yes | R24: Yes | S24: N/A | U24: Yes
A26: 8352 | B26: 5 Sanscrit Place | C26: Tom | D26: Yes | E26: N/A | F26: Yes | H26: N/A | I26: N/A | K26: N/A | L26: Yes | O26: Yes
A28: 8234 | B28: Melhuish House | C28: Tom
A30: 8214 | B30: 6 Tiroroa Lane | C30: Tom | D30: Yes | E30: N/A | K30: N/A
A32: 6792 | B32: Major Hornbrook | C32: Tom | D32: Yes | E32: Yes | F32: Yes | G32: Yes | H32: N/A | I32: Yes | J32: Yes | K32: Yes | L32: Yes | M32: N/A | N32: Yes | O32: Yes | Q32: NA | U32: Yes
A34: 8840 | B34: Inline Architecture | C34: Tom
A36: 8769 | B36: Percival Bach
A38: 7901 | B38: St Albans Street
A40: 8923 | B40: 4 Perry St
A42: 7864 | B42: Ryans House
A44: 7912 | B44: 71A Fendalton Road | C44: Tom | D44: Yes | E44: N/A | G44: 45979 | J44: N/A | K44: N/A | O44: No
A46: 8360 | B46: Dixon House | C46: Tom | D46: Yes | E46: N/A | F46: Yes | G46: 45979 | H46: N/A | I46: Yes | J46: N/A | K46: N/A | L46: N/A | M46: N/A | O46: Yes
A48: 8337 | B48: Waimak Dairys
A50: 9240 | B50: Daves Twizel Shack
A52: 7428 | B52: FAB Pegasus Lakeside | C52: Tom | D52: Yes | E52: N/A | F52: Yes | G52: 45979 | H52: Yes | J52: N/A | K52: N/A | L52: N/A | O52: No
A54: 9351 | B54: Harewood Golf Club | C54: Tom
A56: 7429 | B56: Taggart House | C56: Tom | D56: Yes | E56: N/A | F56: Yes | G56: 45979 | H56: N/A | I56: N/A | J56: N/A | K56: N/A | L56: N/A | O56: No
A58: 9508 | B58: St Barnabas Church | C58: Tom | E58: N/A | F58: Yes | G58: 45979 | H58: N/A | I58: N/A | J58: N/A | K58: N/A | L58: N/A | O58: No
E60: N/A | F60: Yes | H60: N/A | J60: N/A
B62: Contracting
A64: 8946 | B64: Westcoast Vaults | C64: Cameron | D64: Yes | E64: N/A | F64: Yes | G64: Yes | H64: Yes | I64: Yes | J64: Yes | K64: Yes | L64: Yes | N64: Yes | Q64: Yes | R64: Yes | S64: Yes | U64: Yes
A66: 8308 | B66: Roydvale | C66: Tom | E66: N/A | F66: Yes | H66: N/A | J66: N/A
A68: 8530 | B68: 224 Cashel St - Eastern WC Block Reno

Sheet Deliverables Sheet
A1: Updated Job Spreadsheet
A2: Job Number | B2: Job Name | C2: Week | D2: Quoted Price | E2: Claim to date | F2: Remaining to claim | G2: % Claim remaining | H2: Total quoted cost | I2: Total actual cost | J2: Quoted material cost | K2: Actual material cost | L2: Material cost remaining | M2: Material % remaining | N2: Estimated % of materials recieved | O2: Quoted labour cost | P2: Actual labour cost | Q2: Labour cost remaining | R2: Labour cost % remaining | S2: Quoted labour hours | T2: Actual labour hours | U2: Labour hours remaining | V2: Labour hour % remaining | W2: Estimated % of job complete | X2: GP $ Per Hour | Y2: Quoted GP $ Per Hour | Z2: Margin to date | AA2: Quoted margin
AH3: Hours calcs | AI3: Materials calcs
A4: 7658 | B4: Charity Hospital | C4: Start of month | D4: 245679.5 | E4: 216530.08 | F4: 29149.42 | G4: 0.11864816 | H4: 208360.5 | I4: 167957.68 | J4: 180366.49 | K4: 138548.02 | L4: 41818.47 | M4: 0.23185277 | N4: 0.9 | O4: 27994.01 | P4: 29409.66 | Q4: -1415.65 | R4: -0.050569747 | S4: 565.45 | T4: 588.25 | U4: -22.8 | V4: -0.040321868 | X4: 82.571016 | Y4: 65.998776 | Z4: 0.2243 | AA4: 0.1519 | AD4: Hours calc for monthly claims | AE4: -418 | AH4: -418 | AI4: -92952.56
C5: Week 1 | D5: 245679.5 | E5: 216530.08 | F5: 29149.42 | G5: 0.11864816 | H5: 208360.5 | I5: 168361.6 | J5: 180366.49 | K5: 138438.46 | L5: 41928.03 | M5: 0.2324602 | O5: 27994.01 | P5: 29923.14 | Q5: -1929.13 | R5: -0.068912242 | S5: 565.45 | T5: 600.25 | U5: -34.8 | V5: -0.061543903 | X5: 80.247364 | Y5: 65.998776 | Z5: 0.2225 | AA5: 0.1519 | AD5: Materials calc for monthly claims | AE5: -92952.56
C6: Week 2 | D6: 245679.5 | E6: 216530.08 | F6: 29149.42 | G6: 0.11864816 | H6: 208360.5 | I6: 168361.6 | J6: 180366.49 | K6: 138438.46 | L6: 41928.03 | M6: 0.2324602 | O6: 27994.01 | P6: 29923.14 | Q6: -1929.13 | R6: -0.068912242 | S6: 565.45 | T6: 600.25 | U6: -34.8 | V6: -0.061543903 | X6: 80.247364 | Y6: 65.998776 | Z6: 0.2225 | AA6: 0.1519
C7: Week 3 | AD7: Estimated months claim | AE7: 0
C8: Week 4
C9: Week 5 | AH9: -418 | AI9: -92952.56
A11: 8142 | B11: Fisher Developements | C11: Start of month | D11: 129074.86 | E11: 85864.08 | F11: 43210.78 | G11: 0.33477301 | H11: 101420.72 | I11: 74137.32 | J11: 83645.65 | K11: 69538.04 | L11: 14107.61 | M11: 0.16865922 | O11: 17775.07 | P11: 4599.28 | Q11: 13175.79 | R11: 0.74125109 | S11: 356.07 | T11: 93.25 | U11: 262.82 | V11: 0.73811329 | W11: 0.3 | X11: 125.75614 | Y11: 77.66491 | Z11: 0.1366 | AA11: 0.2142 | AD11: Hours calc for monthly claims | AE11: -52.5 | AH11: -52.5 | AI11: -45701.86
C12: Week 1 | D12: 129074.86 | E12: 85864.08 | F12: 43210.78 | G12: 0.33477301 | H12: 101420.72 | I12: 79791.03 | J12: 83645.65 | K12: 71604.5 | L12: 12041.15 | M12: 0.14395429 | O12: 17775.07 | P12: 8186.53 | Q12: 9588.54 | R12: 0.53943754 | S12: 356.07 | T12: 168.25 | U12: 187.82 | V12: 0.52748055 | X12: 36.095394 | Y12: 77.66491 | Z12: 0.0707 | AA12: 0.2142 | AD12: Materials calc for monthly claims | AE12: -45701.86
C13: Week 2 | D13: 129996.92 | E13: 85864.08 | F13: 44132.84 | G13: 0.33949143 | H13: 101885.52 | I13: 79864.19 | J13: 83735.42 | K13: 71677.66 | L13: 12057.76 | M13: 0.14399832 | O13: 18150.1 | P13: 8186.53 | Q13: 9963.57 | R13: 0.548954 | S13: 363.57 | T13: 168.25 | U13: 195.32 | V13: 0.53722804 | X13: 35.660565 | Y13: 77.320439 | Z13: 0.0699 | AA13: 0.2162
C14: Week 3 | AD14: Estimated months claim | AE14: 0
C15: Week 4
C16: Week 5 | AH16: -52.5 | AI16: -45701.86
A18: 8824 | B18: 3 Innovation Road | C18: Start of month | D18: 27500.32 | E18: 11999.08 | F18: 15501.24 | G18: 0.5636749 | H18: 19565.83 | I18: 7621.92 | J18: 13767.34 | K18: 5911.24 | L18: 7856.1 | M18: 0.57063311 | O18: 5798.49 | P18: 1710.68 | Q18: 4087.81 | R18: 0.70497837 | S18: 125.39 | T18: 34.75 | U18: 90.64 | V18: 0.72286466 | W18: 0.25 | X18: 125.96144 | Y18: 63.278465 | Z18: 0.3648 | AA18: 0.2885 | AD18: Hours calc for monthly claims | AE18: -34.75 | AH18: -34.75 | AI18: -5911.24
C19: Week 1 | D19: 27500.32 | E19: 11999.08 | F19: 15501.24 | G19: 0.5636749 | H19: 19565.83 | I19: 7921.92 | J19: 13767.34 | K19: 6211.24 | L19: 7556.1 | M19: 0.54884241 | O19: 5798.49 | P19: 1710.68 | Q19: 4087.81 | R19: 0.70497837 | S19: 125.39 | T19: 34.75 | U19: 90.64 | V19: 0.72286466 | X19: 117.32835 | Y19: 63.278465 | Z19: 0.3398 | AA19: 0.2885 | AD19: Materials calc for monthly claims | AE19: -5911.24
C20: Week 2 | D20: 27500.32 | E20: 11999.08 | F20: 15501.24 | G20: 0.5636749 | H20: 19565.83 | I20: 7921.92 | J20: 13767.34 | K20: 6211.24 | L20: 7556.1 | M20: 0.54884241 | O20: 5798.49 | P20: 1710.68 | Q20: 4087.81 | R20: 0.70497837 | S20: 125.39 | T20: 34.75 | U20: 90.64 | V20: 0.72286466 | X20: 117.32835 | Y20: 63.278465 | Z20: 0.3398 | AA20: 0.2885
C21: Week 3 | AD21: Estimated months claim | AE21: 0
C22: Week 4
C23: Week 5 | AH23: -34.75 | AI23: -5911.24
A25: 8127 | B25: Rolly Autowash | C25: Start of month | D25: 150850.82 | E25: 144370.8 | F25: 6480.02 | G25: 0.042956478 | H25: 102178.42 | I25: 85848.41 | J25: 62464.86 | K25: 57454 | L25: 5010.86 | M25: 0.080218862 | N25: 0.9 | O25: 39713.56 | P25: 28394.41 | Q25: 11319.15 | R25: 0.28501978 | S25: 795.22 | T25: 577.75 | U25: 217.47 | V25: 0.27347149 | W25: 0.6 | X25: 101.29362 | Y25: 61.206215 | Z25: 0.4054 | AA25: 0.3227 | AD25: Hours calc for monthly claims | AE25: -388.25 | AH25: -388.25 | AI25: -56964.81
C26: Week 1 | D26: 150850.82 | E26: 144370.8 | F26: 6480.02 | G26: 0.042956478 | H26: 102178.42 | I26: 89222.05 | J26: 62464.86 | K26: 58984 | L26: 3480.86 | M26: 0.055725091 | O26: 39713.56 | P26: 30238.05 | Q26: 9475.51 | R26: 0.23859634 | S26: 795.22 | T26: 615 | U26: 180.22 | V26: 0.22662911 | X26: 89.672764 | Y26: 61.206215 | Z26: 0.382 | AA26: 0.3227 | AD26: Materials calc for monthly claims | AE26: -56964.81
C27: Week 2 | D27: 153553.67 | E27: 144370.8 | F27: 9182.87 | G27: 0.059802348 | H27: 104026.09 | I27: 89600.47 | J27: 63812.49 | K27: 59331.43 | L27: 4481.06 | M27: 0.070222303 | O27: 40213.6 | P27: 30269.04 | Q27: 9944.56 | R27: 0.24729345 | S27: 805.22 | T27: 615.5 | U27: 189.72 | V27: 0.23561263 | X27: 88.985102 | Y27: 61.50814 | Z27: 0.3794 | AA27: 0.3225
C28: Week 3 | AD28: Estimated months claim | AE28: 0
C29: Week 4
C30: Week 5 | AH30: -388.25 | AI30: -56964.81
A32: 8183 | B32: Murney - 1 Freight Drive + 109 Iport | C32: Start of month | D32: 396422.03 | E32: 259347.71 | F32: 137074.32 | G32: 0.34577877 | H32: 327431.12 | I32: 216344.6 | J32: 271519.78 | K32: 195955.93 | L32: 75563.85 | M32: 0.27829961 | O32: 55911.34 | P32: 20388.67 | Q32: 35522.67 | R32: 0.63533927 | S32: 1120.27 | T32: 476.25 | U32: 644.02 | V32: 0.57487927 | W32: 0.4 | X32: 90.295244 | Y32: 61.584182 | Z32: 0.1658 | AA32: 0.174 | AD32: Hours calc for monthly claims | AE32: -387.5 | AH32: -387.5 | AI32: -132316.71
C33: Week 1 | D33: 396422.03 | E33: 259347.71 | F33: 137074.32 | G33: 0.34577877 | H33: 327431.12 | I33: 223659.54 | J33: 271519.78 | K33: 197370.72 | L33: 74149.06 | M33: 0.27308898 | O33: 55911.34 | P33: 26288.82 | Q33: 29622.52 | R33: 0.52981238 | S33: 1120.27 | T33: 607.75 | U33: 512.52 | V33: 0.45749685 | X33: 58.721794 | Y33: 61.584182 | Z33: 0.1376 | AA33: 0.174 | AD33: Materials calc for monthly claims | AE33: -132316.71
C34: Week 2 | D34: 397238.61 | E34: 259347.71 | F34: 137890.9 | G34: 0.34712361 | H34: 328046.93 | I34: 223743.65 | J34: 271925.57 | K34: 197386.58 | L34: 74538.99 | M34: 0.27411541 | O34: 56121.36 | P34: 26357.07 | Q34: 29764.29 | R34: 0.53035582 | S34: 1124.47 | T34: 609 | U34: 515.47 | V34: 0.45841152 | X34: 58.463153 | Y34: 61.532703 | Z34: 0.1373 | AA34: 0.1742
C35: Week 3 | AD35: Estimated months claim | AE35: 0
C36: Week 4
C37: Week 5 | AH37: -387.5 | AI37: -132316.71
A39: 8886 | B39: Monkey Toe - Fisher fit out | C39: Start of month | D39: 128258.5 | E39: 53944.83 | F39: 74313.67 | G39: 0.57940542 | H39: 94098.32 | I39: 42273.69 | J39: 69042.09 | K39: 35075.75 | L39: 33966.34 | M39: 0.4919657 | O39: 25056.23 | P39: 7197.94 | Q39: 17858.29 | R39: 0.71272853 | S39: 501.83 | T39: 143 | U39: 358.83 | V39: 0.71504294 | W39: 0.4 | X39: 81.616364 | Y39: 68.071224 | Z39: 0.2164 | AA39: 0.2663 | AD39: Hours calc for monthly claims | AE39: -112 | AH39: -112 | AI39: -26847.46
C40: Week 1 | D40: 128258.5 | E40: 53944.83 | F40: 74313.67 | G40: 0.57940542 | H40: 94098.32 | I40: 49261.61 | J40: 69042.09 | K40: 35683.74 | L40: 33358.35 | M40: 0.48315962 | O40: 25056.23 | P40: 13577.87 | Q40: 11478.36 | R40: 0.45810403 | S40: 501.83 | T40: 299.5 | U40: 202.33 | V40: 0.40318435 | X40: 15.636795 | Y40: 68.071224 | Z40: 0.0868 | AA40: 0.2663 | AD40: Materials calc for monthly claims | AE40: -26847.46
C41: Week 2 | D41: 128258.5 | E41: 53944.83 | F41: 74313.67 | G41: 0.57940542 | H41: 94098.32 | I41: 49519.82 | J41: 69042.09 | K41: 35683.74 | L41: 33358.35 | M41: 0.48315962 | O41: 25056.23 | P41: 13836.08 | Q41: 11220.15 | R41: 0.44779881 | S41: 501.83 | T41: 308.25 | U41: 193.58 | V41: 0.38574816 | X41: 14.355264 | Y41: 68.071224 | Z41: 0.082 | AA41: 0.2663
C42: Week 3 | AD42: Estimated months claim | AE42: 0
C43: Week 4
C44: Week 5 | AH44: -112 | AI44: -26847.46
A46: 8887 | B46: Tenancy 2 - Fisher Fit out | C46: Start of month | D46: 65693.36 | E46: 33326.49 | F46: 32366.87 | G46: 0.49269622 | H46: 50582.37 | I46: 25211.58 | J46: 39438.99 | K46: 20456.64 | L46: 18982.35 | M46: 0.48130923 | N46: 0 | O46: 11143.38 | P46: 4754.94 | Q46: 6388.44 | R46: 0.57329464 | S46: 223.22 | T46: 104.25 | U46: 118.97 | V46: 0.53297196 | W46: 0.4 | X46: 77.840863 | Y46: 67.695505 | Z46: 0.2435 | AA46: 0.23 | AD46: Hours calc for monthly claims | AE46: -86.75 | AH46: -86.75 | AI46: -15639.05
...

Sheet Claim Calculator By Month
A1: Updated Job Spreadsheet
A2: Job Number | B2: Job Name | C2: Claim | D2: Costs | E2: Profit | F2: Retention | G2: Margin | H2: Quoted Margin | I2: Hours to complete before E.O.M | J2: Costs to come before E.O.M | K2: Total cost to come before E.O.M | L2: Estimated margin E.O.M | M2: GP End of month | N2: Hours this month | O2: GP $ per hour this month
A4: 7658 | B4: Charity Hospital | C4: 0 | D4: 403.92 | E4: -403.92 | F4: 0 | G4: 0 | H4: 0.2149 | I4: 50 | J4: 5000 | K4: 7000 | L4: 0 | M4: -7403.92 | N4: 20 | O4: -105.77029
A6: 8142 | B6: Fisher Developements | C6: 0 | D6: 5726.87 | E6: -5726.87 | F6: 0 | G6: 0 | H6: 0.23921459 | I6: 40 | J6: 272.6 | K6: 1872.6 | L6: 0 | M6: -7599.47 | N6: -52.5 | O6: 607.9576 | Q6: 14 Mirrors and 49 Downlights have been ordered
A8: 8824 | B8: 3 Innovation Road | C8: 0 | D8: 300 | E8: -300 | G8: 0 | H8: 0.28852355 | I8: 16 | K8: 640 | L8: 0 | M8: -940 | N8: -34.75 | O8: 50.133333
A10: 8127 | B10: Rolly Autowash | C10: 0 | D10: 3752.06 | E10: -3752.06 | F10: 0 | G10: 0 | H10: 0.32265254 | I10: 48 | J10: 3000 | K10: 4920 | L10: 0 | M10: -8672.06 | N10: -388.25 | O10: 25.487318
A12: 8183 | B12: Murney Custodian - 1 Freight Drive | C12: 0 | D12: 7399.05 | E12: -7399.05 | F12: 3 | G12: 0 | H12: 0.17631626 | I12: 16 | J12: 2000 | K12: 2640 | L12: 0 | M12: -10036.05 | N12: 53 | O12: -145.45 | Q12: Couldnt get this rite because of ers but they re claiming 30%
A14: 8886 | B14: Monkey Toe - Fisher fit out | C14: 0 | D14: 7246.13 | E14: -7246.13 | F14: 0 | G14: 0 | H14: 0.26633853 | I14: 0 | J14: 3000 | K14: 3000 | L14: 0 | M14: -10246.13 | N14: -112 | O14: 91.483304
A16: 8887 | B16: Tenancy 2 - Fisher Fit out | C16: 0 | D16: -15.22 | E16: 15.22 | G16: 0 | H16: 0.22635382 | I16: 0 | J16: 3000 | K16: 3000 | L16: 0 | M16: -2984.78 | N16: -86.75 | O16: 34.406686
A18: 8670 | B18: Studio DB - tautara fit out | C18: 0 | D18: 2657.63 | E18: -2657.63 | F18: 0 | G18: 0 | H18: 0.29653766 | I18: 80 | J18: 5000 | K18: 8200 | L18: 0 | M18: -10857.63 | N18: -269 | O18: 57.447778 | Q18: 48 Hours need to be made non Billable
A20: 8907 | B20: 35 Mania | C20: 0 | D20: 0 | E20: 0 | G20: 0 | H20: 0.22334745 | K20: 0 | L20: 0 | M20: 0 | O20: 0
A22: 9065 | B22: Cooltranz stage 4 | C22: 0 | D22: 6826.49 | E22: -6826.49 | F22: 3 | G22: 0 | H22: 0.25248826 | K22: 0 | L22: 0 | M22: -6823.49 | O22: 0
A24: 9259 | B24: Andrew Reeve Stage 2 | C24: 0 | D24: -864.04 | E24: 864.04 | F24: 3 | G24: 0 | K24: 0 | L24: 0 | M24: 867.04 | O24: 0
A26: 8352 | B26: 5 Sanscrit Place | C26: 0 | D26: -1125.88 | E26: 1125.88 | F26: 0 | G26: 0 | H26: 0.34792939 | J26: 0 | K26: 0 | L26: 0 | M26: 1125.88 | N26: -143.25 | O26: -7.8595462
A28: 8234 | B28: Melhuish House | C28: 0 | D28: -945.46 | E28: 945.46 | F28: 0 | G28: 0 | H28: 0.27182514 | K28: 0 | L28: 0 | M28: 945.46 | N28: -148.5 | O28: -6.366734
A30: 8214 | B30: 6 Tiroroa Lane | C30: 0 | D30: 0 | E30: 0 | F30: 0 | G30: 0 | H30: 0.25804338 | K30: 0 | L30: 0 | M30: 0 | N30: -5 | O30: 0
A32: 6792 | B32: Major Hornbrook | C32: -715 | D32: 245.73 | E32: -960.73 | F32: 0 | G32: 1.3436783 | H32: 0.28317296 | I32: 64 | J32: 0 | K32: 2560 | L32: 4.9240979 | M32: -3520.73 | N32: -317.25 | O32: 13.902192
A34: 8840 | B34: Inline Architecture | C34: 0 | D34: 923.88 | E34: -923.88 | F34: 0 | G34: 0 | H34: 0.36418204 | J34: 0 | K34: 0 | L34: 0 | M34: -923.88 | N34: -204.75 | O34: 4.5122344
A36: 8769 | B36: Percival Bach | C36: 0 | D36: 0 | E36: 0 | F36: 0 | G36: 0 | I36: 80 | J36: 0 | K36: 3200 | L36: 0 | M36: -3200 | O36: -40
A38: 7901 | B38: St Albans Street | C38: 52040.56 | D38: 576.98 | E38: 51463.58 | F38: 0 | G38: 0.98891288 | H38: 0.17509217 | K38: 0 | L38: 0.98891288 | M38: 51463.58 | O38: 0
A40: 8923 | B40: 4 Perry St | C40: 2127.81 | D40: 0 | E40: 2127.81 | F40: 0 | G40: 1 | H40: 0.26269298 | J40: 0 | K40: 0 | L40: 1 | M40: 2127.81 | N40: -2 | O40: -1063.905
A42: 7864 | B42: Ryans House | C42: 0 | D42: -13.37 | E42: 13.37 | G42: 0 | H42: 0.25724571 | I42: 0 | K42: 0 | L42: 0 | M42: 13.37 | N42: -266.75 | O42: -0.050121837
A44: 7912 | B44: 71A Fendalton Road | C44: 0 | D44: 0 | E44: 0 | G44: 0 | K44: 0 | L44: 0 | M44: 0 | O44: 0
A46: 8360 | B46: Dixon House | C46: 0 | D46: 0 | E46: 0 | G46: 0 | H46: 0.3058095 | K46: 0 | L46: 0 | M46: 0 | N46: -260.75 | O46: 0
A48: 8337 | B48: Waimak Dairys | C48: 0 | D48: 0 | E48: 0 | G48: 0 | H48: 0.22235078 | J48: 2530 | K48: 2530 | L48: 0 | M48: -2530 | N48: -44.75 | O48: 56.536313
A50: 9240 | B50: Daves Twizel Shack | C50: 0 | D50: 2116.21 | E50: -2116.21 | G50: 0 | I50: 0 | K50: 0 | L50: 0 | M50: -2116.21 | O50: 0 | Q50: $18627.12 from Sharp Electrical
A52: 7428 | B52: FAB Pegasus Lakeside | C52: 0 | D52: 2236.75 | E52: -2236.75 | G52: 0 | H52: 0.21598649 | I52: 32 | J52: 0 | K52: 1280 | L52: 0 | M52: -3516.75 | N52: -304.75 | O52: 12.893676
A54: 9351 | B54: Harewood Golf Club | C54: 0 | D54: 0 | E54: 0 | G54: 0 | H54: 0.45398706 | I54: 16 | J54: 0 | K54: 640 | L54: 0 | M54: -640 | N54: -11.25 | O54: -134.73684
A56: 7429 | B56: Taggart House | C56: 0 | D56: 0 | E56: 0 | G56: 0 | H56: 0.22356151 | I56: 10 | J56: 5000 | K56: 5400 | L56: 0 | M56: -5400 | N56: -32.25 | O56: 242.69663
A58: 9508 | B58: St Barnabas Church | C58: 0 | D58: 0 | E58: 0 | G58: 0 | K58: 0 | L58: 0 | M58: 0 | O58: 0
B62: Contracting | I62: 0
A64: 8946 | B64: Westcoast Vaults | C64: 0 | D64: 4470.96 | E64: -4470.96 | G64: 0 | H64: 0.14379005 | J64: 1750 | K64: 1750 | L64: 0 | M64: -6220.96 | O64: 0
A66: 8308 | B66: Roydvale | C66: 34650.4 | D66: 12036.18 | E66: 22614.22 | G66: 0.65263951 | H66: 0.25626552 | I66: 80 | J66: 0 | K66: 3200 | L66: 0.56028848 | M66: 19414.22 | N66: -1014.25 | O66: -20.780541
A67: ='Main Sheet'!A68 | B67: ='Main Sheet'!B68 | E67: =C67-D67 | G67: =(E67+F67)/C67 | H67: ='Deliverables Sheet'!AA228 | K67: =(I67*40)+J67 | L67: =((E67-K67)+F67)/C67 | M67: =SUM(E67:F67)-K67 | O67: =SUM(M67/(N67+I67))
A70: Totals | B70: Total | C70: 88103.77 | D70: 53954.87 | E70: 34148.9 | F70: GP% | G70: 0.38759862 | H70: E.O.M GP% | I70: -0.20071445
B71: Residential | C71: -22865.6 | D71: 32774.04 | E71: -55639.64 | G71: 2.4333339 | H71: E.O.M GP% | I71: 2.6852407

Sheet Upcoming Work Calculator
A1: Updated Job Spreadsheet
B2: Job | C2: Quoted Hours | D2: Hours Used | E2: Hours Remaining | F2: January | G2: February | H2: March | I2: April | J2: May | K2: June | L2: July | M2: August | N2: September | O2: October | P2: November | Q2: December
A3: Servicing | B3: Servicing work any job under 30 hours | F3: 500 | G3: 700 | H3: 700 | I3: 700 | J3: 700 | K3: 700 | L3: 700 | M3: 700 | N3: 700 | O3: 700 | P3: 700 | Q3: 500
A4: 7658 | B4: Charity Hospital | C4: 565.45 | D4: 600.25 | E4: -34.8 | F4: 0 | G4: 0 | H4: 0 | M4: 80 | S4: Programme Checked 24/03/26
A6: 8142 | B6: Fisher Developements | C6: 363.57 | D6: 168.25 | E6: 195.32 | N6: 80 | S6: Cant find a Programme for this.
A8: 8824 | B8: 3 Innovation Road | C8: 125.39 | D8: 34.75 | E8: 90.64 | N8: 90 | S8: Programme Checked 24/03/26
A10: 8127 | B10: Rolly Autowash | C10: 805.22 | D10: 615.5 | E10: 189.72 | M10: 200 | N10: 80 | O10: 0 | S10: Programme Checked 24/03/26
A12: 8183 | B12: Murney Custodian - 1 Freight Drive | C12: 1124.47 | D12: 609 | E12: 515.47 | M12: 160 | N12: 320 | O12: 80 | S12: Programme Checked 24/03/26
A14: 8886 | B14: Monkey Toe - Fisher fit out | C14: 501.83 | D14: 308.25 | E14: 193.58 | L14: 0 | M14: 80 | N14: 300 | S14: Programme Checked 24/03/26
A16: 8887 | B16: Tenancy 2 - Fisher Fit out | C16: 223.22 | D16: 113.25 | E16: 109.97 | M16: 16 | N16: 110
A18: 8670 | B18: Studio DB - tautara fit out | C18: 685.48 | D18: 561.5 | E18: 123.98 | M18: 240 | N18: 160
A20: 8907 | B20: 35 Mania | C20: 63.5 | D20: 48.25 | E20: 15.25 | M20: 36
A22: 9065 | B22: Cooltranz stage 4 | C22: 193.32 | D22: 2.75 | E22: 190.57 | M22: 20 | N22: 80 | O22: 60
A24: 9259 | B24: Andrew Reeve Stage 2 | C24: 472.14 | D24: 144.25 | E24: 327.89 | M24: 188 | N24: 282
A26: 8352 | B26: 5 Sanscrit Place | C26: 139.07 | D26: 147.75 | E26: -8.68 | M26: 48
A28: 8234 | B28: Melhuish House | C28: 231.75 | D28: 225.5 | E28: 6.25 | M28: 32
A30: 8214 | B30: 6 Tiroroa Lane | C30: 147.9 | D30: 5 | E30: 142.9 | N30: 48 | O30: 16 | P30: 64
A32: 6792 | B32: Major Hornbrook | C32: 208.2 | D32: 324.25 | E32: -116.05
A34: 8840 | B34: Inline Architecture | C34: 324.19 | D34: 472.75 | E34: -148.56 | M34: 130
A36: 8769 | B36: Percival Bach | C36: 84.05 | D36: 0 | E36: 84.05 | M36: 30 | N36: 50
A38: 7901 | B38: St Albans Street | C38: 317.92 | D38: 106 | E38: 211.92 | M38: 80 | N38: 40 | O38: 160
A40: 8923 | B40: 4 Perry St | C40: 156.69 | D40: 11.5 | E40: 145.19 | F40: 60 | G40: 15 | H40: 90
A42: 7864 | B42: Ryans House | C42: 200.82 | D42: 283.75 | E42: -82.93
A44: 7912 | B44: 71A Fendalton Road | C44: 497.55 | D44: 58.25 | E44: 439.3 | F44: 80 | N44: 40 | O44: 300 | P44: 150 | Q44: 150
A46: 8360 | B46: Dixon House | C46: 210.6 | D46: 260.75 | E46: -50.15
A48: 8337 | B48: Waimak Dairys | C48: 110.44 | D48: 60.75 | E48: 49.69 | M48: 16 | N48: 32
A50: 9240 | B50: Daves Twizel Shack | C50: 65.13 | D50: 24.33 | E50: 40.8 | M50: 16 | N50: 40
A52: 7428 | B52: FAB Pegasus Lakeside | C52: 659.73 | D52: 548.75 | E52: 110.98 | M52: 80 | N52: 80 | O52: 180
A54: 9351 | B54: Harewood Golf Club | C54: 125.17 | D54: 23.75 | E54: 101.42 | L54: 16 | M54: 32 | N54: 65
A56: 7429 | B56: Taggart House | C56: 130.62 | D56: 34.75 | E56: 95.87 | M56: 16 | N56: 70
A58: 9508 | B58: St Barnabas Church | C58: 140.15 | D58: 5.75 | E58: 134.4 | O58: 52 | P58: 13 | Q58: 69
B62: Contracting
A64: 8946 | B64: Westcoast Vaults | C64: 358.86 | D64: 0 | E64: 358.86 | N64: 143 | P64: 215
A66: 8308 | B66: Roydvale | C66: 2344.68 | D66: 1401.92 | E66: 942.76 | M66: 320 | N66: 250 | O66: 250 | P66: 240 | Q66: 80
A67: ='Main Sheet'!A68 | B67: ='Main Sheet'!B68 | C67: =LOOKUP(2,1/('Deliverables Sheet'!S229:S233<>0),'Deliverables Sheet'!S229:S233) | D67: =LOOKUP(2,1/('Deliverables Sheet'!T229:T233<>0),'Deliverables Sheet'!T229:T233) | E67: =LOOKUP(2,1/('Deliverables Sheet'!U229:U233<>0),'Deliverables Sheet'!U229:U233)
B71: Total Hours | F71: 640 | G71: 715 | H71: 790 | I71: 700 | J71: 700 | K71: 700 | L71: 716 | M71: 2520 | N71: 3060 | O71: 1316 | P71: 914 | Q71: 650
B72: Residential Hours | F72: 140 | G72: 15 | H72: 90 | L72: 16 | M72: 800 | N72: 858 | O72: 476 | P72: 214 | Q72: 150
B73: Commercial Hours | C73: 4490.26 | M73: 1020 | N73: 1502 | O73: 140
B74: Hours Available | F74: 1488 | G74: 2112 | H74: 1984 | I74: 1884.8 | J74: 1948.8 | K74: 2083.2 | L74: 2604.8 | M74: 2486.4 | N74: 2604.8 | O74: 2217.6 | P74: 2112 | Q74: 1478.4
B75: Balance Hours | F75: -848 | G75: -1397 | H75: -1194 | I75: -1184.8 | J75: -1248.8 | K75: -1383.2 | L75: -1888.8 | M75: 33.6 | N75: 455.2 | O75: -901.6 | P75: -1198 | Q75: -828.4
...

Sheet Note Cam (To Do)
A2: Cams Notes
A3: Koawa:
A4: New job meeting set up for 8am wednesday - Tim, Dylan, VD, Cam - Perhaps bring in Jacob once back from leave??
A5: Tray shop drawings into engineers - waiting on geoff to send back multidraw drawings.
A6: DB dates for sites (livening 11 July)
A7: Confirm Warrenties agreement
A8: Go to tech submissions meeting on Wednesday 12th March
A9: Start getting orders in, (so far PDL gear ordered through rads) need to look at lights beign ordered that we can - confirm process.
A12: Tru Hire:
A13: Temp should be on Monday morning 14.04.25
A14: Craig would like an export/list for me please mate that captures all of the costs to date from you guys and ILS?
A15: Riccarton High:
... A50: Comes up with hours tracking solution

Sheet Note Tom (To Do) 
A2: Tom's Notes:
A38: Other:
A39: Comes up with hours tracking solution

Sheet Deliverables_RR_Test_Sheet (2)
A1: Updated Job Spreadsheet
A2: Job Number | B2: Job Name | C2: Week | D2: Quoted Price | E2: Claim to date | F2: Remaining to claim | G2: % Claim remaining | H2: Total quoted cost | I2: Total actual cost | J2: Quoted material cost | K2: Actual material cost | L2: Material cost remaining | M2: Material % remaining | N2: Estimated % of materials recieved | O2: Contractor Quoted Cost | P2: Contractor Actual Cost | Q2: Contractor Balance | R2: Quoted labour cost | S2: Actual labour cost | T2: Labour cost remaining | U2: Labour cost % remaining | V2: Quoted labour hours | W2: Actual labour hours | X2: Labour hours remaining | Y2: Labour hour % remaining | Z2: Estimated % of job complete | AA2: GP $ Per Hour | AB2: Quoted GP $ Per Hour | AC2: Margin to date | AD2: Quoted margin
AK3: Hours calcs | AL3: Materials calcs
A4: ='Main Sheet'!A4 -> 7658 | B4: ='Main Sheet'!B4 -> Charity Hospital | C4: Start of month | D4: 1914143.5 | E4: 1667392.4 | F4: =D4-E4 -> 246751.12 | G4: =F4/D4 -> 0.12890941 | H4: 1675578 | I4: 1406264.8 | J4: =SUM(H4-(R4+O4)) -> 1511021.4 | K4: =SUM(I4-(S4+P4)) -> 1215391.4 | L4: =J4-K4 -> 295630 | M4: =L4/J4 -> 0.19564911 | O4: 5 | P4: 4 | Q4: =O4-P4 -> 1 | R4: 164551.54 | S4: 190869.33 | T4: =R4-S4 -> -26317.79 | U4: =T4/R4 -> -0.15993646 | V4: 3296.1 | W4: 4599 | X4: =V4-W4 -> -1302.9 | Y4: =X4/V4 -> -0.39528534 | AA4: =(E4-K4-S4)/W4 -> 56.780087 | AB4: =(D4-J4-R4)/V4 -> 72.37964 | AC4: =(E4-K4-S4)/E4 -> 0.15661078 | AD4: =SUM(D4-H4)/D4 -> 0.12463304 | AG4: Hours calc for monthly claims | AH4: =AK9 -> -4599 | AK4: =SUM(W5-W4) -> 415.49 | AL4: =SUM(K5-K4) -> 48650.89
C5: Week 1 | D5: 1922479.9 | E5: 1667392.4 | F5: =D5-E5 -> 255087.52 | G5: =F5/D5 -> 0.1326867 | H5: 1681960.6 | I5: 1474477.1 | J5: =SUM(H5-R5) -> 1516687.4 | K5: =SUM(I5-S5) -> 1264042.3 | L5: =J5-K5 -> 252645.09 | M5: =L5/J5 -> 0.1665769 | R5: 165273.18 | S5: 210434.8 | T5: =R5-S5 -> -45161.62 | U5: =T5/R5 -> -0.27325438 | V5: 3312.1 | W5: 5014.49 | X5: =V5-W5 -> -1702.39 | Y5: =X5/V5 -> -0.51399112 | AA5: =(E5-K5-S5)/W5 -> 38.471561 | AB5: =(D5-J5-R5)/V5 -> 72.618372 | AC5: =(E5-K5-S5)/E5 -> 0.11569878 | AD5: =SUM(D5-H5)/D5 -> 0.12510888 | AG5: Materials calc for monthly claims | AH5: =AL9 -> -1215391.4 | AK5: =SUM(W6-W5) -> 134.5 | AL5: =SUM(K6-K5) -> 24752.67
C6: Week 2 | D6: 1922479.9 | E6: 1667392.4 | F6: =D6-E6 -> 255087.52 | G6: =F6/D6 -> 0.1326867 | H6: 1681960.6 | I6: 1505572.2 | J6: =SUM(H6-R6) -> 1516687.4 | K6: =SUM(I6-S6) -> 1288795 | L6: =J6-K6 -> 227892.42 | M6: =L6/J6 -> 0.15025668 | N6: 0.9 | R6: 165273.18 | S6: 216777.2 | T6: =R6-S6 -> -51504.02 | U6: =T6/R6 -> -0.31162963 | V6: 3312.1 | W6: 5148.99 | X6: =V6-W6 -> -1836.89 | Y6: =X6/V6 -> -0.5545998 | Z6: 0.9 | AA6: =(E6-K6-S6)/W6 -> 31.42756 | AB6: =(D6-J6-R6)/V6 -> 72.618372 | AC6: =(E6-K6-S6)/E6 -> 0.097049855 | AD6: =SUM(D6-H6)/D6 -> 0.12510888 | AK6: =SUM(W7-W6) -> -5148.99 | AL6: =SUM(K7-K6) -> -1288795
C7: Week 3 | F7: =D7-E7 -> 0 | G7: =F7/D7 -> #DIV/0! | J7: =SUM(H7-R7) -> 0 | K7: =SUM(I7-S7) -> 0 | L7: =J7-K7 -> 0 | M7: =L7/J7 -> #DIV/0! | T7: =R7-S7 -> 0 | U7: =T7/R7 -> #DIV/0! | X7: =V7-W7 -> 0 | Y7: =X7/V7 -> #DIV/0! | AA7: =(E7-K7-S7)/W7 -> #DIV/0! | AB7: =(D7-J7-R7)/V7 -> #DIV/0! | AC7: =(E7-K7-S7)/E7 -> #DIV/0! | AD7: =SUM(D7-H7)/D7 -> #DIV/0! | AG7: Estimated months claim | AH7: 0 | AK7: =SUM(W8-W7) -> 0 | AL7: =SUM(K8-K7) -> 0
C8: Week 4 | F8: =D8-E8 -> 0 | G8: =F8/D8 -> #DIV/0! | J8: =SUM(H8-R8) -> 0 | K8: =SUM(I8-S8) -> 0 | L8: =J8-K8 -> 0 | M8: =L8/J8 -> #DIV/0! | T8: =R8-S8 -> 0 | U8: =T8/R8 -> #DIV/0! | X8: =V8-W8 -> 0 | Y8: =X8/V8 -> #DIV/0! | AA8: =(E8-K8-S8)/W8 -> #DIV/0! | AB8: =(D8-J8-R8)/V8 -> #DIV/0! | AC8: =(E8-K8-S8)/E8 -> #DIV/0! | AD8: =SUM(D8-H8)/D8 -> #DIV/0! | AK8: =SUM(W9-W8) -> 0 | AL8: =SUM(K9-K8) -> 0
C9: Week 5 | F9: =D9-E9 -> 0 | G9: =F9/D9 -> #DIV/0! | J9: =SUM(H9-R9) -> 0 | K9: =SUM(I9-S9) -> 0 | L9: =J9-K9 -> 0 | M9: =L9/J9 -> #DIV/0! | T9: =R9-S9 -> 0 | U9: =T9/R9 -> #DIV/0! | X9: =V9-W9 -> 0 | Y9: =X9/V9 -> #DIV/0! | AA9: =(E9-K9-S9)/W9 -> #DIV/0! | AB9: =(D9-J9-R9)/V9 -> #DIV/0! | AC9: =(E9-K9-S9)/E9 -> #DIV/0! | AD9: =SUM(D9-H9)/D9 -> #DIV/0! | AK9: =SUM(AK4,AK5,AK6,AK7,AK8) -> -4599 | AL9: =SUM(AL4,AL5,AL6,AL7,AL8) -> -1215391.4
A11: ='Main Sheet'!A6 -> 8142 | B11: ='Main Sheet'!B6 -> Fisher Developements | C11: Start of month | D11: 381671.63 | E11: 144223.4 | F11: =D11-E11 -> 237448.23 | G11: =F11/D11 -> 0.62212701 | H11: 329257.09 | I11: 168819.17 | J11: =SUM(H11-R11) -> 288248.16 | K11: =SUM(I11-S11) -> 158648.53 | L11: =J11-K11 -> 129599.63 | M11: =L11/J11 -> 0.4496113 | R11: 41008.93 | S11: 10170.64 | T11: =R11-S11 -> 30838.29 | U11: =T11/R11 -> 0.75198963 | V11: 821.2 | W11: 241 | X11: =V11-W11 -> 580.2 | Y11: =X11/V11 -> 0.70652703 | AA11: =(E11-K11-S11)/W11 -> -102.05714 | AB11: =(D11-J11-R11)/V11 -> 63.826766 | AC11: =(E11-K11-S11)/E11 -> -0.17053939 | AD11: =SUM(D11-H11)/D11 -> 0.13732889 | AG11: Hours calc for monthly claims | AH11: =AK16 -> -241 | AK11: =SUM(W12-W11) -> 96.25 | AL11: =SUM(K12-K11) -> 30474.42
C12: Week 1 | D12: 382219.49 | E12: 240065.55 | F12: =D12-E12 -> 142153.94 | G12: =F12/D12 -> 0.37191704 | H12: 329585.81 | I12: 202828.2 | J12: =SUM(H12-R12) -> 288352.94 | K12: =SUM(I12-S12) -> 189122.95 | L12: =J12-K12 -> 99229.99 | M12: =L12/J12 -> 0.34412685 | R12: 41232.87 | S12: 13705.25 | T12: =R12-S12 -> 27527.62 | U12: =T12/R12 -> 0.66761348 | V12: 825.68 | W12: 337.25 | X12: =V12-W12 -> 488.43 | Y12: =X12/V12 -> 0.59154878 | AA12: =(E12-K12-S12)/W12 -> 110.41468 | AB12: =(D12-J12-R12)/V12 -> 63.745858 | AC12: =(E12-K12-S12)/E12 -> 0.15511326 | AD12: =SUM(D12-H12)/D12 -> 0.13770538 | AG12: Materials calc for monthly claims | AH12: =AL16 -> -158648.53 | AK12: =SUM(W13-W12) -> 101.75 | AL12: =SUM(K13-K12) -> 7119.32
C13: Week 2 | D13: 382219.49 | E13: 240065.55 | F13: =D13-E13 -> 142153.94 | G13: =F13/D13 -> 0.37191704 | H13: 329585.81 | I13: 213730.54 | J13: =SUM(H13-R13) -> 288352.94 | K13: =SUM(I13-S13) -> 196242.27 | L13: =J13-K13 -> 92110.67 | M13: =L13/J13 -> 0.31943725 | R13: 41232.87 | S13: 17488.27 | T13: =R13-S13 -> 23744.6 | U13: =T13/R13 -> 0.57586581 | V13: 825.68 | W13: 439 | X13: =V13-W13 -> 386.68 | Y13: =X13/V13 -> 0.46831702 | AA13: =(E13-K13-S13)/W13 -> 59.988633 | AB13: =(D13-J13-R13)/V13 -> 63.745858 | AC13: =(E13-K13-S13)/E13 -> 0.10969925 | AD13: =SUM(D13-H13)/D13 -> 0.13770538 | AK13: =SUM(W14-W13) -> -439 | AL13: =SUM(K14-K13) -> 23228
C14: Week 3 | D14: 383409.63 | E14: 240065.55 | F14: =D14-E14 -> 143344.08 | G14: =F14/D14 -> 0.37386667 | H14: 330537 | I14: 246817.11 | J14: 289155.03 | K14: 219470.27 | L14: =J14-K14 -> 69684.76 | M14: =L14/J14 -> 0.24099446 | N14: 0.75 | T14: =R14-S14 -> 0 | U14: =T14/R14 -> #DIV/0! | X14: =V14-W14 -> 0 | Y14: =X14/V14 -> #DIV/0! | AA14: =(E14-K14-S14)/W14 -> #DIV/0! | AB14: =(D16-J14-R14)/V14 -> #DIV/0! | AC14: =(E14-K14-S14)/E14 -> 0.085790235 | AD14: =SUM(D16-H14)/D16 -> 0.13790115 | AG14: Estimated months claim | AH14: 0 | AK14: =SUM(W15-W14) -> 0 | AL14: =SUM(K15-K14) -> -219470.27
C15: Week 4 | D15: 383409.63 | F15: =D15-E15 -> 383409.63 | G15: =F15/D15 -> 1 | J15: =SUM(H15-R15) -> 0 | K15: =SUM(I15-S15) -> 0 | L15: =J15-K15 -> 0 | M15: =L15/J15 -> #DIV/0! | T15: =R15-S15 -> 0 | U15: =T15/R15 -> #DIV/0! | X15: =V15-W15 -> 0 | Y15: =X15/V15 -> #DIV/0! | AA15: =(E15-K15-S15)/W15 -> #DIV/0! | AB15: =(D15-J15-R15)/V15 -> #DIV/0! | AC15: =(E15-K15-S15)/E15 -> #DIV/0! | AD15: =SUM(D15-H15)/D15 -> 1 | AK15: =SUM(W16-W15) -> 0 | AL15: =SUM(K16-K15) -> 0
C16: Week 5 | D16: 383409.63 | F16: =D16-E16 -> 383409.63 | G16: =F16/D16 -> 1 | J16: =SUM(H16-R16) -> 0 | K16: =SUM(I16-S16) -> 0 | L16: =J16-K16 -> 0 | M16: =L16/J16 -> #DIV/0! | N16: 0.55 | T16: =R16-S16 -> 0 | U16: =T16/R16 -> #DIV/0! | X16: =V16-W16 -> 0 | Y16: =X16/V16 -> #DIV/0! | Z16: 0.35 | AA16: =(E16-K16-S16)/W16 -> #DIV/0! | AB16: =(#REF!-J16-R16)/V16 -> #REF! | AC16: =(E16-K16-S16)/E16 -> #DIV/0! | AD16: =SUM(#REF!-H16)/#REF! -> #REF! | AK16: =SUM(AK11,AK12,AK13,AK14,AK15) -> -241 | AL16: =SUM(AL11,AL12,AL13,AL14,AL15) -> -158648.53
A18: 7104 | B18: ='Main Sheet'!B8 -> 3 Innovation Road | C18: Start of month | D18: 449818.08 | E18: 246538.95 | F18: =D18-E18 -> 203279.13 | G18: =F18/D18 -> 0.45191409 | H18: 329858.1 | I18: 251921.97 | J18: =SUM(H18-R18) -> 255282.19 | K18: =SUM(I18-S18) -> 219103.38 | L18: =J18-K18 -> 36178.81 | M18: =L18/J18 -> 0.14172085 | N18: 0 | R18: 74575.91 | S18: 32818.59 | T18: =R18-S18 -> 41757.32 | U18: =T18/R18 -> 0.55993041 | V18: 1493.36 | W18: 799.5 | X18: =V18-W18 -> 693.86 | Y18: =X18/V18 -> 0.4646301 | Z18: 0 | AA18: =(E18-K18-S18)/W18 -> -6.7329831 | AB18: =(D18-J18-R18)/V18 -> 80.328909 | AC18: =(E18-K18-S18)/E18 -> -0.021834359 | AD18: =SUM(D18-H18)/D18 -> 0.26668555 | AG18: Hours calc for monthly claims | AH18: =AK23 -> -799.5 | AK18: =SUM(W19-W18) -> 57.75 | AL18: =SUM(K19-K18) -> -918.26
C19: Week 1 | D19: 449818.08 | E19: 364039.73 | F19: =D19-E19 -> 85778.35 | G19: =F19/D19 -> 0.19069565 | H19: 329858.1 | I19: 253347.64 | J19: =SUM(H19-R19) -> 255282.19 | K19: =SUM(I19-S19) -> 218185.12 | L19: =J19-K19 -> 37097.07 | M19: =L19/J19 -> 0.14531789 | R19: 74575.91 | S19: 35162.52 | T19: =R19-S19 -> 39413.39 | U19: =T19/R19 -> 0.52850029 | V19: 1493.36 | W19: 857.25 | X19: =V19-W19 -> 636.11 | Y19: =X19/V19 -> 0.42595891 | Z19: 0.1 | AA19: =(E19-K19-S19)/W19 -> 129.12463 | AB19: =(D19-J19-R19)/V19 -> 80.328909 | AC19: =(E19-K19-S19)/E19 -> 0.30406596 | AD19: =SUM(D19-H19)/D19 -> 0.26668555 | AG19: Materials calc for monthly claims | AH19: =AL23 -> -219103.38 | AK19: =SUM(W20-W19) -> 93.75 | AL19: =SUM(K20-K19) -> 5813.69
C20: Week 2 | D20: 449818.08 | E20: 364039.73 | F20: =D20-E20 -> 85778.35 | G20: =F20/D20 -> 0.19069565 | H20: 329858.1 | I20: 262942.02 | J20: =SUM(H20-R20) -> 255282.19 | K20: =SUM(I20-S20) -> 223998.81 | L20: =J20-K20 -> 31283.38 | M20: =L20/J20 -> 0.12254431 | R20: 74575.91 | S20: 38943.21 | T20: =R20-S20 -> 35632.7 | U20: =T20/R20 -> 0.47780443 | V20: 1493.36 | W20: 951 | X20: =V20-W20 -> 542.36 | Y20: =X20/V20 -> 0.36318101 | Z20: 0.15 | AA20: =(E20-K20-S20)/W20 -> 106.30674 | AB20: =(D20-J20-R20)/V20 -> 80.328909 | AC20: =(E20-K20-S20)/E20 -> 0.27771065 | AD20: =SUM(D20-H20)/D20 -> 0.26668555 | AK20: =SUM(W21-W20) -> -951 | AL20: =SUM(K21-K20) -> -223998.81
C21: Week 3 | F21: =D21-E21 -> 0 | G21: =F21/D21 -> #DIV/0! | J21: =SUM(H21-R21) -> 0 | K21: =SUM(I21-S21) -> 0 | L21: =J21-K21 -> 0 | M21: =L21/J21 -> #DIV/0! | T21: =R21-S21 -> 0 | U21: =T21/R21 -> #DIV/0! | X21: =V21-W21 -> 0 | Y21: =X21/V21 -> #DIV/0! | Z21: 0.03 | AA21: =(E21-K21-S21)/W21 -> #DIV/0! | AB21: =(D21-J21-R21)/V21 -> #DIV/0! | AC21: =(E21-K21-S21)/E21 -> #DIV/0! | AD21: =SUM(D21-H21)/D21 -> #DIV/0! | AG21: Estimated months claim | AH21: 0 | AK21: =SUM(W22-W21) -> 0 | AL21: =SUM(K22-K21) -> 0
C22: Week 4 | F22: =D22-E22 -> 0 | G22: =F22/D22 -> #DIV/0! | J22: =SUM(H22-R22) -> 0 | K22: =SUM(I22-S22) -> 0 | L22: =J22-K22 -> 0 | M22: =L22/J22 -> #DIV/0! | T22: =R22-S22 -> 0 | U22: =T22/R22 -> #DIV/0! | X22: =V22-W22 -> 0 | Y22: =X22/V22 -> #DIV/0! | Z22: 0.03 | AA22: =(E22-K22-S22)/W22 -> #DIV/0! | AB22: =(D22-J22-R22)/V22 -> #DIV/0! | AC22: =(E22-K22-S22)/E22 -> #DIV/0! | AD22: =SUM(D22-H22)/D22 -> #DIV/0! | AK22: =SUM(W23-W22) -> 0 | AL22: =SUM(K23-K22) -> 0
C23: Week 5 | F23: =D23-E23 -> 0 | G23: =F23/D23 -> #DIV/0! | J23: =SUM(H23-R23) -> 0 | K23: =SUM(I23-S23) -> 0 | L23: =J23-K23 -> 0 | M23: =L23/J23 -> #DIV/0! | N23: 0.9 | T23: =R23-S23 -> 0 | U23: =T23/R23 -> #DIV/0! | X23: =V23-W23 -> 0 | Y23: =X23/V23 -> #DIV/0! | Z23: 0.65 | AA23: =(E23-K23-S23)/W23 -> #DIV/0! | AB23: =(D23-J23-R23)/V23 -> #DIV/0! | AC23: =(E23-K23-S23)/E23 -> #DIV/0! | AD23: =SUM(D23-H23)/D23 -> #DIV/0! | AK23: =SUM(AK18,AK19,AK20,AK21,AK22) -> -799.5 | AL23: =SUM(AL18,AL19,AL20,AL21,AL22) -> -219103.38
A25: ='Main Sheet'!A10 -> 8127 | B25: ='Main Sheet'!B10 -> Rolly Autowash | C25: Start of month | D25: 38856.96 | E25: 0 | F25: =D25-E25 -> 38856.96 | G25: =F25/D25 -> 1 | H25: 27050.88 | I25: 1129.12 | J25: =SUM(H25-R25) -> 16492.08 | K25: =SUM(I25-S25) -> 1129.12 | L25: =J25-K25 -> 15362.96 | M25: =L25/J25 -> 0.93153562 | N25: 0 | R25: 10558.8 | S25: 0 | T25: =R25-S25 -> 10558.8 | U25: =T25/R25 -> 1 | V25: 213 | W25: 0 | X25: =V25-W25 -> 213 | Y25: =X25/V25 -> 1 | Z25: 0 | AA25: =(E25-K25-S25)/W25 -> #DIV/0! | AB25: =(D25-J25-R25)/V25 -> 55.427606 | AC25: =(E25-K25-S25)/E25 -> #DIV/0! | AD25: =SUM(D25-H25)/D25 -> 0.30383437 | AG25: Hours calc for monthly claims | AH25: =AK30 -> 0 | AK25: =SUM(W26-W25) -> 9.25 | AL25: =SUM(K26-K25) -> 5779.58
C26: Week 1 | D26: 38856.96 | E26: 0 | F26: =D26-E26 -> 38856.96 | G26: =F26/D26 -> 1 | H26: 27050.88 | I26: 7293.59 | J26: =SUM(H26-R26) -> 16492.08 | K26: =SUM(I26-S26) -> 6908.7 | L26: =J26-K26 -> 9583.38 | M26: =L26/J26 -> 0.58108983 | N26: 0 | R26: 10558.8 | S26: 384.89 | T26: =R26-S26 -> 10173.91 | U26: =T26/R26 -> 0.96354794 | V26: 213.13 | W26: 9.25 | X26: =V26-W26 -> 203.88 | Y26: =X26/V26 -> 0.95659926 | Z26: 0 | AA26: =(E26-K26-S26)/W26 -> -788.49622 | AB26: =(D26-J26-R26)/V26 -> 55.393797 | AC26: =(E26-K26-S26)/E26 -> #DIV/0! | AD26: =SUM(D26-H26)/D26 -> 0.30383437 | AG26: Materials calc for monthly claims | AH26: =AL30 -> -1129.12 | AK26: =SUM(W27-W26) -> 101.75 | AL26: =SUM(K27-K26) -> 6796.13
C27: Week 2 | D27: 38856.96 | E27: 0 | F27: =D27-E27 -> 38856.96 | G27: =F27/D27 -> 1 | H27: 27050.88 | I27: 18431.21 | J27: =SUM(H27-R27) -> 16492.08 | K27: =SUM(I27-S27) -> 13704.83 | L27: =J27-K27 -> 2787.25 | M27: =L27/J27 -> 0.16900536 | N27: 0 | R27: 10558.8 | S27: 4726.38 | T27: =R27-S27 -> 5832.42 | U27: =T27/R27 -> 0.55237527 | V27: 213.13 | W27: 111 | X27: =V27-W27 -> 102.13 | Y27: =X27/V27 -> 0.4791911 | Z27: 0 | AA27: =(E27-K27-S27)/W27 -> -166.04694 | AB27: =(D27-J27-R27)/V27 -> 55.393797 | AC27: =(E27-K27-S27)/E27 -> #DIV/0! | AD27: =SUM(D27-H27)/D27 -> 0.30383437 | AK27: =SUM(W28-W27) -> -111 | AL27: =SUM(K28-K27) -> -13704.83
C28: Week 3 | E28: 0 | F28: =D28-E28 -> 0 | G28: =F28/D28 -> #DIV/0! | J28: =SUM(H28-R28) -> 0 | K28: =SUM(I28-S28) -> 0 | L28: =J28-K28 -> 0 | M28: =L28/J28 -> #DIV/0! | N28: 0 | S28: 0 | T28: =R28-S28 -> 0 | U28: =T28/R28 -> #DIV/0! | W28: 0 | X28: =V28-W28 -> 0 | Y28: =X28/V28 -> #DIV/0! | Z28: 0 | AA28: =(E28-K28-S28)/W28 -> #DIV/0! | AB28: =(D28-J28-R28)/V28 -> #DIV/0! | AC28: =(E28-K28-S28)/E28 -> #DIV/0! | AD28: =SUM(D28-H28)/D28 -> #DIV/0! | AG28: Estimated months claim | AH28: 0 | AK28: =SUM(W29-W28) -> 0 | AL28: =SUM(K29-K28) -> 0
C29: Week 4 | E29: 0 | F29: =D29-E29 -> 0 | G29: =F29/D29 -> #DIV/0! | J29: =SUM(H29-R29) -> 0 | K29: =SUM(I29-S29) -> 0 | L29: =J29-K29 -> 0 | M29: =L29/J29 -> #DIV/0! | N29: 0 | S29: 0 | T29: =R29-S29 -> 0 | U29: =T29/R29 -> #DIV/0! | W29: 0 | X29: =V29-W29 -> 0 | Y29: =X29/V29 -> #DIV/0! | Z29: 0 | AA29: =(E29-K29-S29)/W29 -> #DIV/0! | AB29: =(D29-J29-R29)/V29 -> #DIV/0! | AC29: =(E29-K29-S29)/E29 -> #DIV/0! | AD29: =SUM(D29-H29)/D29 -> #DIV/0! | AK29: =SUM(W30-W29) -> 0 | AL29: =SUM(K30-K29) -> 0
C30: Week 5 | E30: 0 | F30: =D30-E30 -> 0 | G30: =F30/D30 -> #DIV/0! | J30: =SUM(H30-R30) -> 0 | K30: =SUM(I30-S30) -> 0 | L30: =J30-K30 -> 0 | M30: =L30/J30 -> #DIV/0! | N30: 0 | S30: 0 | T30: =R30-S30 -> 0 | U30: =T30/R30 -> #DIV/0! | W30: 0 | X30: =V30-W30 -> 0 | Y30: =X30/V30 -> #DIV/0! | Z30: 0 | AA30: =(E30-K30-S30)/W30 -> #DIV/0! | AB30: =(D30-J30-R30)/V30 -> #DIV/0! | AC30: =(E30-K30-S30)/E30 -> #DIV/0! | AD30: =SUM(D30-H30)/D30 -> #DIV/0! | AK30: =SUM(AK25,AK26,AK27,AK28,AK29) -> 0 | AL30: =SUM(AL25,AL26,AL27,AL28,AL29) -> -1129.12
A32: ='Main Sheet'!A12 -> 8183 | B32: ='Main Sheet'!B12 -> Murney - 1 Freight Drive + 109 Iport | C32: Start of month | D32: 69191.71 | E32: 0 | F32: =D32-E32 -> 69191.71 | G32: =F32/D32 -> 1 | H32: 53243.87 | I32: 641.28 | J32: =SUM(H32-R32) -> 41588.94 | K32: =SUM(I32-S32) -> 171.84 | L32: =J32-K32 -> 41417.1 | M32: =L32/J32 -> 0.99586813 | R32: 11654.93 | S32: 469.44 | T32: =R32-S32 -> 11185.49 | U32: =T32/R32 -> 0.95972177 | V32: 233.59 | W32: 12.5 | X32: =V32-W32 -> 221.09 | Y32: =X32/V32 -> 0.94648744 | Z32: 0 | AA32: =(E32-K32-S32)/W32 -> -51.3024 | AB32: =(D32-J32-R32)/V32 -> 68.272786 | AC32: =(E32-K32-S32)/E32 -> #DIV/0! | AD32: =SUM(D32-H32)/D32 -> 0.23048773 | AG32: Hours calc for monthly claims | AH32: =AK37 -> -12.5 | AK32: =SUM(W33-W32) -> 4.5 | AL32: =SUM(K33-K32) -> 13.95
C33: Week 1 | D33: 69191.71 | E33: 1364.78 | F33: =D33-E33 -> 67826.93 | G33: =F33/D33 -> 0.98027538 | H33: 53243.87 | I33: 844.77 | J33: =SUM(H33-R33) -> 41588.94 | K33: =SUM(I33-S33) -> 185.79 | L33: =J33-K33 -> 41403.15 | M33: =L33/J33 -> 0.99553271 | R33: 11654.93 | S33: 658.98 | T33: =R33-S33 -> 10995.95 | U33: =T33/R33 -> 0.94345912 | V33: 233.59 | W33: 17 | X33: =V33-W33 -> 216.59 | Y33: =X33/V33 -> 0.92722291 | AA33: =(E33-K33-S33)/W33 -> 30.588824 | AB33: =(D33-J33-R33)/V33 -> 68.272786 | AC33: =(E33-K33-S33)/E33 -> 0.38102112 | AD33: =SUM(D33-H33)/D33 -> 0.23048773 | AG33: Materials calc for monthly claims | AH33: =AL37 -> -171.84 | AK33: =SUM(W34-W33) -> 3 | AL33: =SUM(K34-K33) -> 3907.37
C34: Week 2 | D34: 69191.71 | E34: 1364.78 | F34: =D34-E34 -> 67826.93 | G34: =F34/D34 -> 0.98027538 | H34: 53243.87 | I34: 4850.24 | J34: =SUM(H34-R34) -> 41588.94 | K34: =SUM(I34-S34) -> 4093.16 | L34: =J34-K34 -> 37495.78 | M34: =L34/J34 -> 0.90158056 | R34: 11654.93 | S34: 757.08 | T34: =R34-S34 -> 10897.85 | U34: =T34/R34 -> 0.93504208 | V34: 233.59 | W34: 20 | X34: =V34-W34 -> 213.59 | Y34: =X34/V34 -> 0.9143799 | AA34: =(E34-K34-S34)/W34 -> -174.273 | AB34: =(D34-J34-R34)/V34 -> 68.272786 | AC34: =(E34-K34-S34)/E34 -> -2.5538622 | AD34: =SUM(D34-H34)/D34 -> 0.23048773 | AK34: =SUM(W35-W34) -> -20 | AL34: =SUM(K35-K34) -> -4093.16
C35: Week 3 | F35: =D35-E35 -> 0 | G35: =F35/D35 -> #DIV/0! | J35: =SUM(H35-R35) -> 0 | K35: =SUM(I35-S35) -> 0 | L35: =J35-K35 -> 0 | M35: =L35/J35 -> #DIV/0! | T35: =R35-S35 -> 0 | U35: =T35/R35 -> #DIV/0! | X35: =V35-W35 -> 0 | Y35: =X35/V35 -> #DIV/0! | AA35: =(E35-K35-S35)/W35 -> #DIV/0! | AB35: =(D35-J35-R35)/V35 -> #DIV/0! | AC35: =(E35-K35-S35)/E35 -> #DIV/0! | AD35: =SUM(D35-H35)/D35 -> #DIV/0! | AG35: Estimated months claim | AH35: 0 | AK35: =SUM(W36-W35) -> 0 | AL35: =SUM(K36-K35) -> 0
C36: Week 4 | F36: =D36-E36 -> 0 | G36: =F36/D36 -> #DIV/0! | J36: =SUM(H36-R36) -> 0 | K36: =SUM(I36-S36) -> 0 | L36: =J36-K36 -> 0 | M36: =L36/J36 -> #DIV/0! | T36: =R36-S36 -> 0 | U36: =T36/R36 -> #DIV/0! | X36: =V36-W36 -> 0 | Y36: =X36/V36 -> #DIV/0! | AA36: =(E36-K36-S36)/W36 -> #DIV/0! | AB36: =(D36-J36-R36)/V36 -> #DIV/0! | AC36: =(E36-K36-S36)/E36 -> #DIV/0! | AD36: =SUM(D36-H36)/D36 -> #DIV/0! | AK36: =SUM(W37-W36) -> 0 | AL36: =SUM(K37-K36) -> 0
C37: Week 5 | F37: =D37-E37 -> 0 | G37: =F37/D37 -> #DIV/0! | J37: =SUM(H37-R37) -> 0 | K37: =SUM(I37-S37) -> 0 | L37: =J37-K37 -> 0 | M37: =L37/J37 -> #DIV/0! | T37: =R37-S37 -> 0 | U37: =T37/R37 -> #DIV/0! | X37: =V37-W37 -> 0 | Y37: =X37/V37 -> #DIV/0! | AA37: =(E37-K37-S37)/W37 -> #DIV/0! | AB37: =(D37-J37-R37)/V37 -> #DIV/0! | AC37: =(E37-K37-S37)/E37 -> #DIV/0! | AD37: =SUM(D37-H37)/D37 -> #DIV/0! | AK37: =SUM(AK32,AK33,AK34,AK35,AK36) -> -12.5 | AL37: =SUM(AL32,AL33,AL34,AL35,AL36) -> -171.84
A39: ='Main Sheet'!A14 -> 8886 | B39: ='Main Sheet'!B14 -> Monkey Toe - Fisher fit out | C39: Start of month | D39: 44956.29 | F39: =D39-E39 -> 44956.29 | G39: =F39/D39 -> 1 | H39: 30585.67 | I39: 0 | J39: =SUM(H39-R39) -> 19268.79 | K39: =SUM(I39-S39) -> 0 | L39: =J39-K39 -> 19268.79 | M39: =L39/J39 -> 1 | R39: 11316.88 | T39: =R39-S39 -> 11316.88 | U39: =T39/R39 -> 1 | V39: 234.28 | W39: 0 | X39: =V39-W39 -> 234.28 | Y39: =X39/V39 -> 1 | Z39: 0.8 | AA39: =(E39-K39-S39)/W39 -> #DIV/0! | AB39: =(D39-J39-R39)/V39 -> 61.339508 | AC39: =(E39-K39-S39)/E39 -> #DIV/0! | AD39: =SUM(D39-H39)/D39 -> 0.31965761 | AG39: Hours calc for monthly claims | AH39: =AK44 -> 0 | AK39: =SUM(W40-W39) -> 0 | AL39: =SUM(K40-K39) -> 0
C40: Week 1 | D40: 44956.29 | F40: =D40-E40 -> 44956.29 | G40: =F40/D40 -> 1 | H40: 30585.67 | J40: =SUM(H40-R40) -> 19268.79 | K40: =SUM(I40-S40) -> 0 | L40: =J40-K40 -> 19268.79 | M40: =L40/J40 -> 1 | R40: 11316.88 | T40: =R40-S40 -> 11316.88 | U40: =T40/R40 -> 1 | V40: 234.28 | W40: 0 | X40: =V40-W40 -> 234.28 | Y40: =X40/V40 -> 1 | Z40: 0.95 | AA40: =(E40-K40-S40)/W40 -> #DIV/0! | AB40: =(D40-J40-R40)/V40 -> 61.339508 | AC40: =(E40-K40-S40)/E40 -> #DIV/0! | AD40: =SUM(D40-H40)/D40 -> 0.31965761 | AG40: Materials calc for monthly claims | AH40: =AL44 -> 0 | AK40: =SUM(W41-W40) -> 2.5 | AL40: =SUM(K41-K40) -> 0
C41: Week 2 | D41: 44956.29 | F41: =D41-E41 -> 44956.29 | G41: =F41/D41 -> 1 | H41: 30585.67 | I41: 112.35 | J41: =SUM(H41-R41) -> 19268.79 | K41: =SUM(I41-S41) -> 0 | L41: =J41-K41 -> 19268.79 | M41: =L41/J41 -> 1 | R41: 11316.88 | S41: 112.35 | T41: =R41-S41 -> 11204.53 | U41: =T41/R41 -> 0.99007235 | V41: 234.28 | W41: 2.5 | X41: =V41-W41 -> 231.78 | Y41: =X41/V41 -> 0.98932901 | Z41: 0.98 | AA41: =(E41-K41-S41)/W41 -> -44.94 | AB41: =(D41-J41-R41)/V41 -> 61.339508 | AC41: =(E41-K41-S41)/E41 -> #DIV/0! | AD41: =SUM(D41-H41)/D41 -> 0.31965761 | AK41: =SUM(W42-W41) -> -2.5 | AL41: =SUM(K42-K41) -> 0
C42: Week 3 | F42: =D42-E42 -> 0 | G42: =F42/D42 -> #DIV/0! | J42: =SUM(H42-R42) -> 0 | K42: =SUM(I42-S42) -> 0 | L42: =J42-K42 -> 0 | M42: =L42/J42 -> #DIV/0! | T42: =R42-S42 -> 0 | U42: =T42/R42 -> #DIV/0! | W42: 0 | X42: =V42-W42 -> 0 | Y42: =X42/V41 -> 0 | Z42: 1 | AA42: =(E42-K42-S42)/W42 -> #DIV/0! | AB42: =(D42-J42-R42)/V41 -> 0 | AC42: =(E42-K42-S42)/E42 -> #DIV/0! | AD42: =SUM(D42-H42)/D42 -> #DIV/0! | AG42: Estimated months claim | AH42: 0 | AK42: =SUM(W43-W42) -> 0 | AL42: =SUM(K43-K42) -> 0
C43: Week 4 | F43: =D43-E43 -> 0 | G43: =F43/D43 -> #DIV/0! | J43: =SUM(H43-R43) -> 0 | K43: =SUM(I43-S43) -> 0 | L43: =J43-K43 -> 0 | M43: =L43/J43 -> #DIV/0! | T43: =R43-S43 -> 0 | U43: =T43/R43 -> #DIV/0! | W43: 0 | X43: =V43-W43 -> 0 | Y43: =X43/V43 -> #DIV/0! | Z43: 1 | AA43: =(E43-K43-S43)/W43 -> #DIV/0! | AB43: =(D43-J43-R43)/V43 -> #DIV/0! | AC43: =(E43-K43-S43)/E43 -> #DIV/0! | AD43: =SUM(D43-H43)/D43 -> #DIV/0! | AK43: =SUM(W44-W43) -> 0 | AL43: =SUM(K44-K43) -> 0
C44: Week 5 | F44: =D44-E44 -> 0 | G44: =F44/D44 -> #DIV/0! | J44: =SUM(H44-R44) -> 0 | K44: =SUM(I44-S44) -> 0 | L44: =J44-K44 -> 0 | M44: =L44/J44 -> #DIV/0! | T44: =R44-S44 -> 0 | U44: =T44/R44 -> #DIV/0! | W44: 0 | X44: =V44-W44 -> 0 | Y44: =X44/V44 -> #DIV/0! | Z44: 1 | AA44: =(E44-K44-S44)/W44 -> #DIV/0! | AB44: =(D44-J44-R44)/V44 -> #DIV/0! | AC44: =(E44-K44-S44)/E44 -> #DIV/0! | AD44: =SUM(D44-H44)/D44 -> #DIV/0! | AK44: =SUM(AK39,AK40,AK41,AK42,AK43) -> 0 | AL44: =SUM(AL39,AL40,AL41,AL42,AL43) -> 0
A46: ='Main Sheet'!A16 -> 8887 | B46: ='Main Sheet'!B16 -> Tenancy 2 - Fisher Fit out | C46: Start of month | D46: 7495.54 | E46: 0 | F46: =D46-E46 -> 7495.54 | G46: =F46/D46 -> 1 | H46: 5659.85 | I46: 0 | J46: =SUM(H46-R46) -> 3768.03 | K46: =SUM(I46-S46) -> 0 | L46: =J46-K46 -> 3768.03 | M46: =L46/J46 -> 1 | N46: 0 | R46: 1891.82 | S46: 0 | T46: =R46-S46 -> 1891.82 | U46: =T46/R46 -> 1 | V46: 37.84 | W46: 0 | X46: =V46-W46 -> 37.84 | Y46: =X46/V46 -> 1 | Z46: 0 | AA46: =(E46-K46-S46)/W46 -> #DIV/0! | AB46: =(D46-J46-R46)/V46 -> 48.511892 | AC46: =(E46-K46-S46)/E46 -> #DIV/0! | AD46: =SUM(D46-H46)/D46 -> 0.2449043 | AG46: Hours calc for monthly claims | AH46: =AK51 -> 0 | AK46: =SUM(W47-W46) -> 0 | AL46: =SUM(K47-K46) -> 0
...

Sheet Sheet1
A3: 340 | B3: Allowed | C3: Actual | D3: % of job
A4: Box out | B4: 30 | D4: =SUM(B4/A3) -> 0.088235294
A5: pre-wire | B5: 60 | P5: 95.35
A6: cut out | B6: 100 | P6: 102.69
A7: fit off lights | B7: 150 | P7: 134.82
P8: 324.19
P9: 415
