Workbook

Sheet Main Sheet
A1: Updated Job Spreadsheet
A2: Job Number | B2: Job Name | C2: Job Owner | D2: Contract Signed & Returned. Retention % loaded correctly into Katipolt | E2: Warranty Signed & Returned | F2: Construction Programme Received | G2: Into Work Calculator 2 Weekly | H2: Temp Application Done | I2: Mains Connection Application | J2: POs Sent to Sub contractors | K2: Switchboard Drawing Sent for Approval | L2: Email Sent to QS/Builder to Confirm Order Gear | M2: Long Lead Time Materials Ordered | O2: Client Walk Through | P2: Pre Job Meeting Completed with Staff Job Pack Made | Q2: O&M Manual underway (notes for what's needed) | R2: QA Completed By Others | T2: Job Completion Paperwork Completed | U2: All V.Os captured | W2: Last toolbox date
M3: Ordered | N3: Lead Times Comm. | R3: 1st Fix | S3: 2nd Fix
A4: 7658 | B4: Charity Hospital | C4: Cameron | D4: Yes | F4: Yes | G4: Yes | H4: N/A | I4: N/A | J4: Yes | K4: Yes | L4: Yes | M4: Yes | P4: Yes
A6: 8142 | B6: Fisher Developements | C6: Cameron | D6: Yes | F6: Yes | G6: yes | H6: Yes | I6: Yes | J6: Yes | K6: Yes | M6: Yes
A8: 8824 | B8: 3 Innovation Road | C8: Cameron
A10: 8127 | B10: Rolly Autowash | C10: Cameron | D10: Yes | F10: Yes | G10: No | H10: Yes | I10: Yes | J10: N/A | K10: Yes | M10: Yes
A12: 8183 | B12: Murney - 1 Freight Drive + 109 Iport | C12: Cameron | D12: Yes | F12: Yes | G12: Yes | H12: Yes | I12: Yes | J12: Yes | K12: Yes | M12: Yes
A14: 8886 | B14: Monkey Toe - Fisher fit out | C14: Cameron | F14: Yes | G14: No | H14: N/A | I14: Yes | J14: Yes | K14: Yes
A16: 8887 | B16: Tenancy 2 - Fisher Fit out | C16: Cameron | F16: Yes | G16: No | H16: N/A | I16: Yes | J16: Yes | K16: Yes
A18: 8670 | B18: Studio DB - tautara fit out | C18: Cameron | D18: Yes
A20: 8907 | B20: 35 Mania | C20: Cameron | D20: Yes
A22: 9065 | B22: Cooltranz stage 4 | C22: Cameron
A24: 9259 | B24: Andrew Reeve Stage 2 | C24: Cameron
A26: 8352 | B26: 5 Sanscrit Place | C26: Tom | D26: Yes | E26: N/A | F26: Yes | H26: N/A | I26: N/A | K26: N/A | L26: Yes | O26: Yes
A28: 8234 | B28: Melhuish House | C28: Tom
A30: 8214 | B30: 6 Tiroroa Lane | C30: Tom | D30: Yes | E30: N/A | K30: N/A
A32: 6792 | B32: Major Hornbrook | C32: Tom | D32: Yes | E32: N/A | F32: Yes | G32: 45979 | H32: Yes | I32: Yes | J32: N/A | K32: N/A | L32: N/A | O32: No | Q32: NA
A34: 8840 | B34: Inline Architecture | C34: Tom
A36: 8769 | B36: Percival Bach
A38: 7901 | B38: St Albans Street
A40: 8923 | B40: 4 Perry St
A42: 7864 | B42: Ryans House
A44: 7912 | B44: 71A Fendalton Road | C44: Tom | D44: Yes | E44: N/A | G44: 45979 | J44: N/A | K44: N/A | O44: No
A46: 8360 | B46: Dixon House | C46: Tom | D46: Yes | E46: N/A | F46: Yes | G46: 45979 | H46: N/A | I46: Yes | J46: N/A | K46: N/A | L46: N/A | M46: N/A | O46: Yes
A48: 8337 | B48: Waimak Dairys
A50: 9240 | B50: Daves Twizel Shack
A52: 7428 | B52: FAB Pegasus Lakeside | C52: Tom | D52: Yes | E52: N/A | F52: Yes | G52: 45979 | H52: Yes | J52: N/A | K52: N/A | L52: N/A | O52: No
A54: 9351 | B54: Harewood Golf Club | C54: Tom
A56: 7429 | B56: Taggart House | C56: Tom | D56: Yes | E56: N/A | F56: Yes | G56: 45979 | H56: N/A | I56: N/A | J56: N/A | K56: N/A | L56: N/A | O56: No
A58: 9508 | B58: St Barnabas Church | C58: Tom | E58: N/A | F58: Yes | G58: 45979 | H58: N/A | I58: N/A | J58: N/A | K58: N/A | L58: N/A | O58: No
E60: N/A | F60: Yes | H60: N/A | J60: N/A
B62: Contracting
A64: 8946 | B64: Westcoast Vaults | C64: Cameron
A66: 8308 | B66: Roydvale | C66: Tom | E66: N/A | F66: Yes | H66: N/A | J66: N/A

Sheet Deliverables Sheet
A1: Updated Job Spreadsheet
A2: Job Number | B2: Job Name | C2: Week | D2: Quoted Price | E2: Claim to date | F2: Remaining to claim | G2: % Claim remaining | H2: Total quoted cost | I2: Total actual cost | J2: Quoted material cost | K2: Actual material cost | L2: Material cost remaining | M2: Material % remaining | N2: Estimated % of materials recieved | O2: Quoted labour cost | P2: Actual labour cost | Q2: Labour cost remaining | R2: Labour cost % remaining | S2: Quoted labour hours | T2: Actual labour hours | U2: Labour hours remaining | V2: Labour hour % remaining | W2: Estimated % of job complete | X2: GP $ Per Hour | Y2: Quoted GP $ Per Hour | Z2: Margin to date | AA2: Quoted margin
AH3: Hours calcs | AI3: Materials calcs
A4: 7658 | B4: Charity Hospital | C4: Start of month | D4: 215046.91 | E4: 205915.9 | F4: 9131.01 | G4: 0.04246055 | H4: 181293.63 | I4: 113522.99 | J4: 155024.75 | K4: 92952.56 | L4: 62072.19 | M4: 0.40040181 | N4: 0.9 | O4: 26268.88 | P4: 20570.43 | Q4: 5698.45 | R4: 0.21692779 | S4: 530.95 | T4: 418 | U4: 112.95 | V4: 0.2127319 | X4: 221.03567 | Y4: 63.571485 | Z4: 0.44869245 | AA4: 0.15695775 | AD4: Hours calc for monthly claims | AE4: -418 | AH4: -418 | AI4: -92952.56
C5: Week 1 | D5: 233882.27 | E5: 205915.9 | F5: 27966.37 | G5: 0.11957456 | H5: 199128.99 | I5: 161636.57 | J5: 172860.11 | K5: 136958.29 | L5: 35901.82 | M5: 0.20769291 | O5: 26268.88 | P5: 24678.28 | Q5: 1590.6 | R5: 0.060550735 | S5: 530.95 | T5: 498.25 | U5: 32.7 | V5: 0.06158772 | X5: 88.869704 | Y5: 65.454902 | Z5: 0.215 | AA5: 0.1486 | AD5: Materials calc for monthly claims | AE5: -92952.56
C6: Week 2
C7: Week 3 | D7: 233882.27 | E7: 205915.9 | F7: 27966.37 | G7: 0.11957456 | H7: 199128.99 | I7: 165210.04 | J7: 172860.11 | K7: 137410.69 | L7: 35449.42 | M7: 0.20507577 | O7: 26268.88 | P7: 27799.35 | Q7: -1530.47 | R7: -0.058261715 | S7: 530.95 | T7: 556.5 | U7: -25.55 | V7: -0.048121292 | X7: 73.146199 | Y7: 65.454902 | Z7: 0.1977 | AA7: 0.1486 | AD7: Estimated months claim | AE7: 0
C8: Week 4
C9: Week 5 | AH9: -418 | AI9: -92952.56
A11: 8142 | B11: Fisher Developements | C11: Start of month | D11: 95023.47 | E11: 51156.11 | F11: 43867.36 | G11: 0.46164763 | H11: 72292.47 | I11: 48296.81 | J11: 56719.74 | K11: 45701.86 | L11: 11017.88 | M11: 0.19425124 | O11: 15572.73 | P11: 2594.95 | Q11: 12977.78 | R11: 0.83336576 | S11: 311.89 | T11: 52.5 | U11: 259.39 | V11: 0.83167142 | W11: 0.3 | X11: 54.462857 | Y11: 72.881465 | Z11: 0.055893617 | AA11: 0.23921459 | AD11: Hours calc for monthly claims | AE11: -52.5 | AH11: -52.5 | AI11: -45701.86
C12: Week 1 | D12: 129074.86 | E12: 55068.11 | F12: 74006.75 | G12: 0.57336301 | H12: 101420.72 | I12: 54810.2 | J12: 83645.65 | K12: 51716.87 | L12: 31928.78 | M12: 0.38171477 | O12: 17775.07 | P12: 3093.33 | Q12: 14681.74 | R12: 0.82597368 | S12: 356.07 | T12: 63 | U12: 293.07 | V12: 0.8230685 | X12: 4.0938095 | Y12: 77.66491 | Z12: 0.0047 | AA12: 0.2142 | AD12: Materials calc for monthly claims | AE12: -45701.86
C13: Week 2
C14: Week 3 | AD14: Estimated months claim | AE14: 0
C15: Week 4
C16: Week 5 | AH16: -52.5 | AI16: -45701.86
A18: 8824 | B18: 3 Innovation Road | C18: Start of month | D18: 27500.32 | E18: 6999.08 | F18: 20501.24 | G18: 0.74549096 | H18: 19565.83 | I18: 7621.92 | J18: 13767.34 | K18: 5911.24 | L18: 7856.1 | M18: 0.57063311 | O18: 5798.49 | P18: 1710.68 | Q18: 4087.81 | R18: 0.70497837 | S18: 125.39 | T18: 34.75 | U18: 90.64 | V18: 0.72286466 | W18: 0.25 | X18: -17.923453 | Y18: 63.278491 | Z18: -0.088988839 | AA18: 0.28852355 | AD18: Hours calc for monthly claims | AE18: -34.75 | AH18: -34.75 | AI18: -5911.24
C19: Week 1 | AD19: Materials calc for monthly claims | AE19: -5911.24
C20: Week 2
C21: Week 3 | AD21: Estimated months claim | AE21: 0
C22: Week 4
C23: Week 5 | AH23: -34.75 | AI23: -5911.24
A25: 8127 | B25: Rolly Autowash | C25: Start of month | D25: 150850.82 | E25: 111983.72 | F25: 38867.1 | G25: 0.25765256 | H25: 102178.42 | I25: 75718.13 | J25: 62464.86 | K25: 56964.81 | L25: 5500.05 | M25: 0.088050305 | N25: 0.9 | O25: 39713.56 | P25: 18753.32 | Q25: 20960.24 | R25: 0.52778547 | S25: 795.22 | T25: 388.25 | U25: 406.97 | V25: 0.51177033 | W25: 0.6 | X25: 93.40783 | Y25: 61.206207 | Z25: 0.32384698 | AA25: 0.32265254 | AD25: Hours calc for monthly claims | AE25: -388.25 | AH25: -388.25 | AI25: -56964.81
C26: Week 1 | D26: 150850.82 | E26: 111983.72 | F26: 38867.1 | G26: 0.25765256 | H26: 102178.42 | I26: 81033.37 | J26: 62464.86 | K26: 58088.59 | L26: 4376.27 | M26: 0.07005971 | O26: 39713.56 | P26: 22944.78 | Q26: 16768.78 | R26: 0.42224318 | S26: 795.22 | T26: 472.75 | U26: 322.47 | V26: 0.40551042 | X26: 65.468747 | Y26: 61.206215 | Z26: 0.2764 | AA26: 0.3227 | AD26: Materials calc for monthly claims | AE26: -56964.81
C27: Week 2
C28: Week 3 | AD28: Estimated months claim | AE28: 0
C29: Week 4
C30: Week 5 | AH30: -388.25 | AI30: -56964.81
A32: 8183 | B32: Murney - 1 Freight Drive + 109 Iport | C32: Start of month | D32: 389022.03 | E32: 176161.65 | F32: 212860.38 | G32: 0.54716793 | H32: 320431.12 | I32: 148939.51 | J32: 264519.78 | K32: 132316.71 | L32: 132203.07 | M32: 0.4997852 | O32: 55911.34 | P32: 16622.8 | Q32: 39288.54 | R32: 0.70269359 | S32: 1120.27 | T32: 387.5 | U32: 732.77 | V32: 0.65410124 | W32: 0.4 | X32: 70.250684 | Y32: 61.227124 | Z32: 0.15452932 | AA32: 0.17631626 | AD32: Hours calc for monthly claims | AE32: -387.5 | AH32: -387.5 | AI32: -132316.71
C33: Week 1 | D33: 396422.03 | E33: 176161.65 | F33: 220260.38 | G33: 0.55562094 | H33: 327431.12 | I33: 150094.16 | J33: 271519.78 | K33: 132259.14 | L33: 139260.64 | M33: 0.51289317 | O33: 55911.34 | P33: 17835.02 | Q33: 38076.32 | R33: 0.68101247 | S33: 1120.27 | T33: 416.25 | U33: 704.02 | V33: 0.62843779 | X33: 62.624601 | Y33: 61.584182 | Z33: 0.148 | AA33: 0.174 | AD33: Materials calc for monthly claims | AE33: -132316.71
C34: Week 2
C35: Week 3 | AD35: Estimated months claim | AE35: 0
C36: Week 4
C37: Week 5 | AH37: -387.5 | AI37: -132316.71
A39: 8886 | B39: Monkey Toe - Fisher fit out | C39: Start of month | D39: 128258.5 | E39: 36398.39 | F39: 91860.11 | G39: 0.7162107 | H39: 94098.32 | I39: 32521.46 | J39: 69042.09 | K39: 26847.46 | L39: 42194.63 | M39: 0.61114358 | O39: 25056.23 | P39: 5674 | Q39: 19382.23 | R39: 0.77354933 | S39: 501 | T39: 112 | U39: 389 | V39: 0.77644711 | W39: 0.4 | X39: 34.615446 | Y39: 68.183992 | Z39: 0.10651378 | AA39: 0.26633853 | AD39: Hours calc for monthly claims | AE39: -112 | AH39: -112 | AI39: -26847.46
C40: Week 1 | D40: 128258.5 | E40: 36398.39 | F40: 91860.11 | G40: 0.7162107 | H40: 94098.32 | I40: 35395.54 | J40: 69042.09 | K40: 29132.06 | L40: 39910.03 | M40: 0.57805362 | O40: 25056.23 | P40: 6263.48 | Q40: 18792.75 | R40: 0.75002305 | S40: 501.83 | T40: 122.75 | U40: 379.08 | V40: 0.75539525 | X40: 8.1698574 | Y40: 68.071224 | Z40: 0.0276 | AA40: 0.2663 | AD40: Materials calc for monthly claims | AE40: -26847.46
C41: Week 2 | D41: 128258.5 | E41: 36398.39 | F41: 91860.11 | G41: 0.7162107 | H41: 94098.32 | I41: 34659.62 | J41: 69042.09 | K41: 28340.06 | L41: 40702.03 | M41: 0.58952488 | O41: 25056.23 | P41: 6319.56 | Q41: 18736.67 | R41: 0.74778488 | S41: 501.83 | T41: 123.75 | U41: 378.08 | V41: 0.75340255 | X41: 14.050667 | Y41: 68.071224 | Z41: 0.0478 | AA41: 0.2663
C42: Week 3 | AD42: Estimated months claim | AE42: 0
C43: Week 4
C44: Week 5 | AH44: -112 | AI44: -26847.46
A46: 8887 | B46: Tenancy 2 - Fisher Fit out | C46: Start of month | D46: 64305.21 | E46: 25322.07 | F46: 38983.14 | G46: 0.60622055 | H46: 49749.48 | I46: 19566.87 | J46: 39151.4 | K46: 15639.05 | L46: 23512.35 | M46: 0.60054941 | N46: 0 | O46: 10598.08 | P46: 3927.82 | Q46: 6670.26 | R46: 0.62938381 | S46: 212.3 | T46: 86.75 | U46: 125.55 | V46: 0.59138012 | W46: 0.4 | X46: 66.342363 | Y46: 68.562082 | Z46: 0.22728 | AA46: 0.22635382 | AD46: Hours calc for monthly claims | AE46: -86.75 | AH46: -86.75 | AI46: -15639.05
...

Sheet Claim Calculator By Month
A1: Updated Job Spreadsheet
A2: Job Number | B2: Job Name | C2: Claim | D2: Costs | E2: Profit | F2: Retention | G2: Margin | H2: Quoted Margin | I2: Hours to complete before E.O.M | J2: Costs to come before E.O.M | K2: Total cost to come before E.O.M | L2: Estimated margin E.O.M | M2: GP End of month | N2: Hours this month | O2: GP $ per hour this month
A4: ='Main Sheet'!A4 -> 7658 | B4: ='Main Sheet'!B4 -> Charity Hospital | C4: 0 | D4: 51687.05 | E4: =C4-D4 -> 9727.83 | F4: 0 | G4: =(E4+F4)/C4 -> 0.4863915 | H4: 0.2149 | I4: 0 | J4: 90 | K4: =(I4*40)+J4 -> 90 | L4: =((E4-K4)+F4)/C4 -> 0.4818915 | M4: =SUM(E4:F4)-K4 -> 9637.83 | N4: 20 | O4: =SUM(M4/(N4+I4)) -> 481.8915
A6: ='Main Sheet'!A6 -> 8142 | B6: ='Main Sheet'!B6 -> Fisher Developements | C6: 3912 | D6: 6513.39 | E6: =C6-D6 -> -3968.93 | F6: 0 | G6: =(E6+F6)/C6 -> #DIV/0! | H6: ='Deliverables Sheet'!AA11 -> 0.23921459 | I6: 16 | J6: 272.6 | K6: =(I6*40)+J6 -> 912.6 | L6: =((E6-K6)+F6)/C6 -> #DIV/0! | M6: =SUM(E6:F6)-K6 -> -4881.53 | N6: ='Deliverables Sheet'!AE11 -> -52.5 | O6: =SUM(M6/(N6+I6)) -> 133.74055 | Q6: 14 Mirrors and 49 Downlights have been ordered
A8: ='Main Sheet'!A8 -> 8824 | B8: ='Main Sheet'!B8 -> 3 Innovation Road | C8: 0 | D8: 0 | E8: =C8-D8 -> 2227.16 | G8: =(E8+F8)/C8 -> 0.31820754 | H8: ='Deliverables Sheet'!AA18 -> 0.28852355 | I8: 16 | K8: =(I8*40)+J8 -> 640 | L8: =((E8-K8)+F8)/C8 -> 0.22676695 | M8: =SUM(E8:F8)-K8 -> 1587.16 | N8: ='Deliverables Sheet'!AE18 -> -34.75 | O8: =SUM(M8/(N8+I8)) -> -84.648533
A10: ='Main Sheet'!A10 -> 8127 | B10: ='Main Sheet'!B10 -> Rolly Autowash | C10: 0 | D10: 5315.24 | E10: =C10-D10 -> 19246.78 | F10: 0 | G10: =(E10+F10)/C10 -> 0.36157089 | H10: ='Deliverables Sheet'!AA25 -> 0.32265254 | I10: 48 | J10: 3000 | K10: 1000 | L10: =((E10-K10)+F10)/C10 -> 0.34278484 | M10: =SUM(E10:F10)-K10 -> 18246.78 | N10: ='Deliverables Sheet'!AE25 -> -388.25 | O10: =SUM(M10/(N10+I10)) -> -53.627568
A12: 8183 | B12: Murney Custodian - 1 Freight Drive | C12: 0 | D12: 1154.65 | E12: =C12-D12 -> 7144.34 | G12: =(E12+F12)/C12 -> 0.35107322 | H12: ='Deliverables Sheet'!AA32 -> 0.17631626 | I12: 16 | J12: 2000 | K12: =(I12*40)+J12 -> 2640 | L12: =((E12-K12)+F12)/C12 -> 0.22134349 | M12: =SUM(E12:F12)-K12 -> 4504.34 | N12: 53 | O12: =SUM(M12/(N12+I12)) -> 65.28029 | Q12: Couldnt get this rite because of ers but they re claiming 30%
A14: ='Main Sheet'!A14 -> 8886 | B14: ='Main Sheet'!B14 -> Monkey Toe - Fisher fit out | C14: 0 | D14: 2138.16 | E14: =C14-D14 -> 3415.11 | F14: 0 | G14: =(E14+F14)/C14 -> 0.3381297 | H14: ='Deliverables Sheet'!AA39 -> 0.26633853 | I14: 0 | J14: 3000 | K14: 0 | L14: =((E14-K14)+F14)/C14 -> 0.3381297 | M14: =SUM(E14:F14)-K14 -> 3415.11 | N14: ='Deliverables Sheet'!AE39 -> -112 | O14: =SUM(M14/(N14+I14)) -> -30.492054
A16: ='Main Sheet'!A16 -> 8887 | B16: ='Main Sheet'!B16 -> Tenancy 2 - Fisher Fit out | C16: 0 | D16: 5565.03 | E16: =C16-D16 -> 5660 | G16: =(E16+F16)/C16 -> 0.53904762 | H16: ='Deliverables Sheet'!AA46 -> 0.22635382 | I16: 0 | J16: 3000 | K16: =(I16*40)+J16 -> 3000 | L16: =((E16-K16)+F16)/C16 -> 0.25333333 | M16: =SUM(E16:F16)-K16 -> 2660 | N16: ='Deliverables Sheet'!AE46 -> -86.75 | O16: =SUM(M16/(N16+I16)) -> -30.662824
A18: ='Main Sheet'!A18 -> 8670 | B18: ='Main Sheet'!B18 -> Studio DB - tautara fit out | C18: 0 | D18: 10982.64 | E18: =C18-D18 -> 16075.1 | F18: 0 | G18: =(E18+F18)/C18 -> 0.43257869 | H18: ='Deliverables Sheet'!AA53 -> 0.29653766 | I18: 80 | J18: 5000 | K18: =(I18*40)+J18 -> 8200 | L18: =((E18-K18)+F18)/C18 -> 0.21191784 | M18: =SUM(E18:F18)-K18 -> 7875.1 | N18: ='Deliverables Sheet'!AE53 -> -269 | O18: =SUM(M18/(N18+I18)) -> -41.667196 | Q18: 48 Hours need to be made non Billable
A20: ='Main Sheet'!A20 -> 8907 | B20: ='Main Sheet'!B20 -> 35 Mania | C20: 0 | D20: 1407.88 | E20: =C20-D20 -> 0 | G20: =(E20+F20)/C20 -> #DIV/0! | H20: ='Deliverables Sheet'!AA60 -> 0.22334745 | K20: =(I20*40)+J20 -> 0 | L20: =((E20-K20)+F20)/C20 -> #DIV/0! | M20: =SUM(E20:F20)-K20 -> 0 | O20: =SUM(M20/(N20+I20)) -> #DIV/0!
A22: ='Main Sheet'!A22 -> 9065 | B22: ='Main Sheet'!B22 -> Cooltranz stage 4 | C22: 0 | D22: 4584.16 | E22: =C22-D22 -> 0 | F22: 0 | G22: =(E22+F22)/C22 -> #DIV/0! | H22: ='Deliverables Sheet'!AA67 -> 0.25248826 | K22: =(I22*40)+J22 -> 0 | L22: =((E22-K22)+F22)/C22 -> #DIV/0! | M22: =SUM(E22:F22)-K22 -> 0 | N22: ='Deliverables Sheet'!AE67 -> 0 | O22: =SUM(M22/(N22+I22)) -> #DIV/0!
A24: ='Main Sheet'!A24 -> 9259 | B24: ='Main Sheet'!B24 -> Andrew Reeve Stage 2 | C24: 0 | D24: 22353.17 | E24: =C24-D24 -> 0 | G24: =(E24+F24)/C24 -> #DIV/0! | H24: ='Deliverables Sheet'!AA74 -> #DIV/0! | K24: =(I24*40)+J24 -> 0 | L24: =((E24-K24)+F24)/C24 -> #DIV/0! | M24: =SUM(E24:F24)-K24 -> 0 | N24: ='Deliverables Sheet'!AE74 -> 0 | O24: =SUM(M24/(N24+I24)) -> #DIV/0!
A26: ='Main Sheet'!A26 -> 8352 | B26: ='Main Sheet'!B26 -> 5 Sanscrit Place | C26: 0 | D26: -192.5 | E26: =C26-D26 -> 0 | F26: 0 | G26: =(E26+F26)/C26 -> #DIV/0! | H26: ='Deliverables Sheet'!AA81 -> 0.34792939 | J26: 0 | K26: =(I26*40)+J26 -> 0 | L26: =((E26-K26)+F26)/C26 -> #DIV/0! | M26: =SUM(E26:F26)-K26 -> 0 | N26: ='Deliverables Sheet'!AE81 -> -143.25 | O26: =SUM(M26/(N26+I26)) -> 0
A28: ='Main Sheet'!A28 -> 8234 | B28: ='Main Sheet'!B28 -> Melhuish House | C28: 0 | D28: 4476.15 | E28: =C28-D28 -> 2313.69 | F28: 0 | G28: =(E28+F28)/C28 -> 0.34629131 | H28: ='Deliverables Sheet'!AA88 -> 0.27182514 | K28: =(I28*40)+J28 -> 0 | L28: =((E28-K28)+F28)/C28 -> 0.34629131 | M28: =SUM(E28:F28)-K28 -> 2313.69 | N28: ='Deliverables Sheet'!AE88 -> -148.5 | O28: =SUM(M28/(N28+I28)) -> -15.580404
A30: ='Main Sheet'!A30 -> 8214 | B30: ='Main Sheet'!B30 -> 6 Tiroroa Lane | C30: 0 | D30: 0 | E30: =C30-D30 -> 0 | F30: 0 | G30: =(E30+F30)/C30 -> #DIV/0! | H30: ='Deliverables Sheet'!AA95 -> 0.25804338 | K30: =(I30*40)+J30 -> 0 | L30: =((E30-K30)+F30)/C30 -> #DIV/0! | M30: =SUM(E30:F30)-K30 -> 0 | N30: ='Deliverables Sheet'!AE95 -> -5 | O30: =SUM(M30/(N30+I30)) -> 0
A32: ='Main Sheet'!A32 -> 6792 | B32: ='Main Sheet'!B32 -> Major Hornbrook | C32: 0 | D32: -1171.89 | E32: =C32-D32 -> 4327.53 | F32: 0 | G32: =(E32+F32)/C32 -> 0.6924048 | H32: ='Deliverables Sheet'!AA102 -> 0.28317296 | I32: 64 | J32: 0 | K32: =(I32*40)+J32 -> 2560 | L32: =((E32-K32)+F32)/C32 -> 0.2828048 | M32: =SUM(E32:F32)-K32 -> 1767.53 | N32: ='Deliverables Sheet'!AE102 -> -317.25 | O32: =SUM(M32/(N32+I32)) -> -6.979388
A34: ='Main Sheet'!A34 -> 8840 | B34: ='Main Sheet'!B34 -> Inline Architecture | C34: -35454.43 | D34: 16334.04 | E34: =C34-D34 -> 0 | F34: 0 | G34: =(E34+F34)/C34 -> #DIV/0! | H34: ='Deliverables Sheet'!AA109 -> 0.36418204 | J34: 0 | K34: =(I34*40)+J34 -> 0 | L34: =((E34-K34)+F34)/C34 -> #DIV/0! | M34: =SUM(E34:F34)-K34 -> 0 | N34: ='Deliverables Sheet'!AE109 -> -204.75 | O34: =SUM(M34/(N34+I34)) -> 0
A36: ='Main Sheet'!A36 -> 8769 | B36: ='Main Sheet'!B36 -> Percival Bach | C36: 0 | D36: 0 | E36: =C36-D36 -> 10702.1 | F36: 0 | G36: =(E36+F36)/C36 -> 0.49473237 | H36: ='Deliverables Sheet'!AA116 -> #DIV/0! | I36: 80 | J36: 0 | K36: =(I36*40)+J36 -> 3200 | L36: =((E36-K36)+F36)/C36 -> 0.34680406 | M36: =SUM(E36:F36)-K36 -> 7502.1 | N36: ='Deliverables Sheet'!AE116 -> 0 | O36: =SUM(M36/(N36+I36)) -> 93.77625
A38: ='Main Sheet'!A38 -> 7901 | B38: ='Main Sheet'!B38 -> St Albans Street | C38: 0 | D38: 6365.78 | E38: =C38-D38 -> 0 | F38: 0 | G38: =(E38+F38)/C38 -> #DIV/0! | H38: ='Deliverables Sheet'!AA123 -> 0.17509217 | K38: =(I38*40)+J38 -> 0 | L38: =((E38-K38)+F38)/C38 -> #DIV/0! | M38: =SUM(E38:F38)-K38 -> 0 | N38: ='Deliverables Sheet'!AE123 -> 0 | O38: =SUM(M38/(N38+I38)) -> #DIV/0!
A40: ='Main Sheet'!A40 -> 8923 | B40: ='Main Sheet'!B40 -> 4 Perry St | C40: 0 | D40: 0 | E40: =C40-D40 -> 0 | F40: 0 | G40: =(E40+F40)/C40 -> #DIV/0! | H40: ='Deliverables Sheet'!AA130 -> 0.26269298 | J40: 0 | K40: =(I40*40)+J40 -> 0 | L40: =((E40-K40)+F40)/C40 -> #DIV/0! | M40: =SUM(E40:F40)-K40 -> 0 | N40: ='Deliverables Sheet'!AE130 -> -2 | O40: =SUM(M40/(N40+I40)) -> 0
A42: ='Main Sheet'!A42 -> 7864 | B42: ='Main Sheet'!B42 -> Ryans House | C42: 3554.3 | D42: 584.89 | E42: =C42-D42 -> -106.2 | G42: =(E42+F42)/C42 -> -0.015830191 | H42: ='Deliverables Sheet'!AA137 -> 0.25724571 | I42: 0 | K42: =(I42*40)+J42 -> 0 | L42: =((E42-K42)+F42)/C42 -> -0.015830191 | M42: =SUM(E42:F42)-K42 -> -106.2 | N42: ='Deliverables Sheet'!AE137 -> -266.75 | O42: =SUM(M42/(N42+I42)) -> 0.39812559
A44: ='Main Sheet'!A44 -> 7912 | B44: ='Main Sheet'!B44 -> 71A Fendalton Road | C44: 9034.53 | D44: 6362.08 | E44: =C44-D44 -> 1991.31 | G44: =(E44+F44)/C44 -> 0.31224921 | H44: ='Deliverables Sheet'!AA144 -> #DIV/0! | K44: =(I44*40)+J44 -> 0 | L44: =((E44-K44)+F44)/C44 -> 0.31224921 | M44: =SUM(E44:F44)-K44 -> 1991.31 | N44: ='Deliverables Sheet'!AE144 -> 0 | O44: =SUM(M44/(N44+I44)) -> #DIV/0!
A46: ='Main Sheet'!A46 -> 8360 | B46: ='Main Sheet'!B46 -> Dixon House | C46: 0 | D46: 15.49 | E46: =C46-D46 -> 651.41 | G46: =(E46+F46)/C46 -> 0.12799574 | H46: ='Deliverables Sheet'!AA151 -> 0.3058095 | K46: =(I46*40)+J46 -> 0 | L46: =((E46-K46)+F46)/C46 -> 0.12799574 | M46: =SUM(E46:F46)-K46 -> 651.41 | N46: ='Deliverables Sheet'!AE151 -> -260.75 | O46: =SUM(M46/(N46+I46)) -> -2.4982167
A48: ='Main Sheet'!A48 -> 8337 | B48: ='Main Sheet'!B48 -> Waimak Dairys | C48: 13424.5 | D48: 2862.01 | E48: =C48-D48 -> 5862.4 | G48: =(E48+F48)/C48 -> 0.4366941 | H48: ='Deliverables Sheet'!AA158 -> 0.22235078 | J48: 2530 | K48: =(I48*40)+J48 -> 2530 | L48: =((E48-K48)+F48)/C48 -> 0.24823271 | M48: =SUM(E48:F48)-K48 -> 3332.4 | N48: ='Deliverables Sheet'!AE158 -> -44.75 | O48: =SUM(M48/(N48+I48)) -> -74.467039
A50: ='Main Sheet'!A50 -> 9240 | B50: ='Main Sheet'!B50 -> Daves Twizel Shack | C50: 0 | D50: 0 | E50: =C50-D50 -> 0 | G50: =(E50+F50)/C50 -> #DIV/0! | H50: ='Deliverables Sheet'!AA165 -> #DIV/0! | I50: 0 | K50: =(I50*40)+J50 -> 0 | L50: =((E50-K50)+F50)/C50 -> #DIV/0! | M50: =SUM(E50:F50)-K50 -> 0 | N50: ='Deliverables Sheet'!AE165 -> 0 | O50: =SUM(M50/(N50+I50)) -> #DIV/0! | Q50: $18627.12 from Sharp Electrical
A52: ='Main Sheet'!A52 -> 7428 | B52: ='Main Sheet'!B52 -> FAB Pegasus Lakeside | C52: 0 | D52: 20350.28 | E52: =C52-D52 -> 2683.58 | G52: =(E52+F52)/C52 -> 0.5707134 | H52: ='Deliverables Sheet'!AA172 -> 0.21598649 | I52: 32 | J52: 0 | K52: =(I52*40)+J52 -> 1280 | L52: =((E52-K52)+F52)/C52 -> 0.2984975 | M52: =SUM(E52:F52)-K52 -> 1403.58 | N52: ='Deliverables Sheet'!AE172 -> -304.75 | O52: =SUM(M52/(N52+I52)) -> -5.1460312
A54: ='Main Sheet'!A54 -> 9351 | B54: ='Main Sheet'!B54 -> Harewood Golf Club | C54: 5491.7 | D54: 756.63 | E54: =C54-D54 -> 2545.55 | G54: =(E54+F54)/C54 -> 0.46352678 | H54: ='Deliverables Sheet'!AA179 -> 0.45398706 | I54: 16 | J54: 0 | K54: =(I54*40)+J54 -> 640 | L54: =((E54-K54)+F54)/C54 -> 0.34698727 | M54: =SUM(E54:F54)-K54 -> 1905.55 | N54: ='Deliverables Sheet'!AE179 -> -11.25 | O54: =SUM(M54/(N54+I54)) -> 401.16842
A56: ='Main Sheet'!A56 -> 7429 | B56: ='Main Sheet'!B56 -> Taggart House | C56: 12937.1 | D56: 4850.19 | E56: =C56-D56 -> 9059.83 | G56: =(E56+F56)/C56 -> 0.70029837 | H56: ='Deliverables Sheet'!AA186 -> 0.22356151 | I56: 10 | J56: 5000 | K56: =(I56*40)+J56 -> 5400 | L56: =((E56-K56)+F56)/C56 -> 0.28289416 | M56: =SUM(E56:F56)-K56 -> 3659.83 | N56: ='Deliverables Sheet'!AE186 -> -32.25 | O56: =SUM(M56/(N56+I56)) -> -164.48674
A58: ='Main Sheet'!A58 -> 9508 | B58: ='Main Sheet'!B58 -> St Barnabas Church | C58: 0 | D58: 7180.07 | E58: =C58-D58 -> 0 | G58: =(E58+F58)/C58 -> #DIV/0! | H58: ='Deliverables Sheet'!AA193 -> #DIV/0! | K58: =(I58*40)+J58 -> 0 | L58: =((E58-K58)+F58)/C58 -> #DIV/0! | M58: =SUM(E58:F58)-K58 -> 0 | N58: ='Deliverables Sheet'!AE193 -> 0 | O58: =SUM(M58/(N58+I58)) -> #DIV/0!
A60: ='Main Sheet'!A60 -> 0 | B60: ='Main Sheet'!B60 -> 0 | E60: =C60-D60 -> 0 | G60: =(E60+F60)/C60 -> #DIV/0! | H60: ='Deliverables Sheet'!AA200 -> #DIV/0! | K60: =(I60*40)+J60 -> 0 | L60: =((E60-K60)+F60)/C60 -> #DIV/0! | M60: =SUM(E60:F60)-K60 -> 0 | N60: ='Deliverables Sheet'!AE200 -> 0 | O60: =SUM(M60/(N60+I60)) -> #DIV/0!
A62: ='Main Sheet'!A62 -> 0 | B62: ='Main Sheet'!B62 -> Contracting | E62: =C62-D62 -> 0 | G62: =(E62+F62)/C62 -> #DIV/0! | H62: ='Deliverables Sheet'!AA207 -> #DIV/0! | I62: 0 | K62: =(I62*40)+J62 -> 0 | L62: =((E62-K62)+F62)/C62 -> #DIV/0! | M62: =SUM(E62:F62)-K62 -> 0 | N62: ='Deliverables Sheet'!AE207 -> 0 | O62: =SUM(M62/(N62+I62)) -> #DIV/0!
A64: ='Main Sheet'!A64 -> 8946 | B64: ='Main Sheet'!B64 -> Westcoast Vaults | C64: 0 | D64: 1749.8 | E64: =C64-D64 -> 0 | G64: =(E64+F64)/C64 -> #DIV/0! | H64: ='Deliverables Sheet'!AA214 -> 0.14379005 | J64: 1750 | K64: =(I64*40)+J64 -> 1750 | L64: =((E64-K64)+F64)/C64 -> #DIV/0! | M64: =SUM(E64:F64)-K64 -> -1750 | N64: ='Deliverables Sheet'!AE214 -> 0 | O64: =SUM(M64/(N64+I64)) -> #DIV/0!
A66: 8308 | B66: ='Main Sheet'!B66 -> Roydvale | C66: 0 | D66: 3855.08 | E66: =C66-D66 -> 11482 | G66: =(E66+F66)/C66 -> 0.37645902 | H66: ='Deliverables Sheet'!AA221 -> 0.25626552 | I66: 80 | J66: 0 | K66: =(I66*40)+J66 -> 3200 | L66: =((E66-K66)+F66)/C66 -> 0.27154098 | M66: =SUM(E66:F66)-K66 -> 8282 | N66: ='Deliverables Sheet'!AE221 -> -1014.25 | O66: =SUM(M66/(N66+I66)) -> -8.8648649
A69: Totals | B69: Commercial | C69: =SUM(C4,C6,C8,C10,C12,C14,C16,C18,C20,C22,C24) -> 158341.18 | D69: =SUM(D4,D6,D8,D10,D12,D14,D16,D18,D20,D22,D24) -> 98813.79 | E69: =SUM(E4,E6,E8,E10,E12,E14,E16,E18,E20,E22,E24) -> 59527.39 | F69: GP% | G69: =SUM(E69/C69) -> 0.37594383 | H69: E.O.M GP% | I69: =(E69-(K4+K6+K8+K10+K12+K14+K16+K18+K20+K22+K24))/C69 -> 0.27184836
B70: Residential | C70: =SUM(C26,C28,C30,C32,C34,C36,C38,C40,C42,C44,C46) -> 52738.76 | D70: =SUM(D26,D28,D30,D32,D34,D36,D38,D40,D42,D44,D46) -> 32858.92 | E70: =SUM(E26,E28,E30,E32,E34,E36,E38,E40,E42,E44,E46) -> 19879.84 | F70: GP% | G70: =SUM(E70/C70) -> 0.37694933 | H70: E.O.M GP% | I70: =(E70-(K26+K28+K30+K32+K34+K36+K38+K40+K42+K44+K46))/C70 -> 0.26773174

Sheet Upcoming Work Calculator
A1: Updated Job Spreadsheet
B2: Job | C2: Quoted Hours | D2: Hours Used | E2: Hours Remaining | F2: January | G2: February | H2: March | I2: April | J2: May | K2: June | L2: July | M2: August | N2: September | O2: October | P2: November | Q2: December
A3: Servicing | B3: Servicing work any job under 30 hours | F3: 500 | G3: 700 | H3: 700 | I3: 700 | J3: 700 | K3: 700 | L3: 700 | M3: 700 | N3: 700 | O3: 700 | P3: 700 | Q3: 500
A4: ='Main Sheet'!A4 -> 7658 | B4: ='Main Sheet'!B4 -> Charity Hospital | C4: {=LOOKUP(2,1/('Deliverables Sheet'!S4:S9<>0),'Deliverables Sheet'!S4:S9)} -> 530.95 | D4: {=LOOKUP(2,1/('Deliverables Sheet'!T4:T9<>0),'Deliverables Sheet'!T4:T9)} -> 418 | E4: {=LOOKUP(2,1/('Deliverables Sheet'!U4:U9<>0),'Deliverables Sheet'!U4:U9)} -> 112.95 | M4: 80 | S4: Programme Checked 24/03/26
A6: ='Main Sheet'!A6 -> 8142 | B6: ='Main Sheet'!B6 -> Fisher Developements | C6: {=LOOKUP(2,1/('Deliverables Sheet'!S11:S16<>0),'Deliverables Sheet'!S11:S16)} -> 311.89 | D6: {=LOOKUP(2,1/('Deliverables Sheet'!T11:T16<>0),'Deliverables Sheet'!T11:T16)} -> 52.5 | E6: {=LOOKUP(2,1/('Deliverables Sheet'!U11:U16<>0),'Deliverables Sheet'!U11:U16)} -> 259.39 | N6: 80 | S6: Cant find a Programme for this.
A8: ='Main Sheet'!A8 -> 8824 | B8: ='Main Sheet'!B8 -> 3 Innovation Road | C8: {=LOOKUP(2,1/('Deliverables Sheet'!S18:S23<>0),'Deliverables Sheet'!S18:S23)} -> 125.39 | D8: {=LOOKUP(2,1/('Deliverables Sheet'!T18:T23<>0),'Deliverables Sheet'!T18:T23)} -> 34.75 | E8: {=LOOKUP(2,1/('Deliverables Sheet'!U18:U23<>0),'Deliverables Sheet'!U18:U23)} -> 90.64 | N8: 90 | S8: Programme Checked 24/03/26
A10: ='Main Sheet'!A10 -> 8127 | B10: ='Main Sheet'!B10 -> Rolly Autowash | C10: {=LOOKUP(2,1/('Deliverables Sheet'!S25:S30<>0),'Deliverables Sheet'!S25:S30)} -> 795.22 | D10: {=LOOKUP(2,1/('Deliverables Sheet'!T25:T30<>0),'Deliverables Sheet'!T25:T30)} -> 388.25 | E10: {=LOOKUP(2,1/('Deliverables Sheet'!U25:U30<>0),'Deliverables Sheet'!U25:U30)} -> 406.97 | M10: 200 | N10: 80 | S10: Programme Checked 24/03/26
A12: 8183 | B12: Murney Custodian - 1 Freight Drive | C12: ='Deliverables Sheet'!S32 -> 1120.27 | D12: ='Deliverables Sheet'!T32 -> 387.5 | E12: {=LOOKUP(2,1/('Deliverables Sheet'!U32:U37<>0),'Deliverables Sheet'!U32:U37)} -> 732.77 | M12: 160 | N12: 320 | O12: 80 | S12: Programme Checked 24/03/26
A14: ='Main Sheet'!A14 -> 8886 | B14: ='Main Sheet'!B14 -> Monkey Toe - Fisher fit out | C14: ='Deliverables Sheet'!S39 -> 501 | D14: ='Deliverables Sheet'!T39 -> 112 | E14: {=LOOKUP(2,1/('Deliverables Sheet'!U39:U44<>0),'Deliverables Sheet'!U39:U44)} -> 389 | L14: 0 | M14: 80 | N14: 300 | S14: Programme Checked 24/03/26
A16: ='Main Sheet'!A16 -> 8887 | B16: ='Main Sheet'!B16 -> Tenancy 2 - Fisher Fit out | C16: {=LOOKUP(2,1/('Deliverables Sheet'!S46:S51<>0),'Deliverables Sheet'!S46:S51)} -> 212.3 | D16: {=LOOKUP(2,1/('Deliverables Sheet'!T46:T51<>0),'Deliverables Sheet'!T46:T51)} -> 86.75 | E16: {=LOOKUP(2,1/('Deliverables Sheet'!U46:U51<>0),'Deliverables Sheet'!U46:U51)} -> 125.55 | M16: 16 | N16: 110
A18: ='Main Sheet'!A18 -> 8670 | B18: ='Main Sheet'!B18 -> Studio DB - tautara fit out | C18: {=LOOKUP(2,1/('Deliverables Sheet'!S53:S58<>0),'Deliverables Sheet'!S53:S58)} -> 668.92 | D18: {=LOOKUP(2,1/('Deliverables Sheet'!T53:T58<>0),'Deliverables Sheet'!T53:T58)} -> 269 | E18: {=LOOKUP(2,1/('Deliverables Sheet'!U53:U58<>0),'Deliverables Sheet'!U53:U58)} -> 399.92 | M18: 240 | N18: 160
A20: ='Main Sheet'!A20 -> 8907 | B20: ='Main Sheet'!B20 -> 35 Mania | C20: {=LOOKUP(2,1/('Deliverables Sheet'!S60:S65<>0),'Deliverables Sheet'!S60:S65)} -> 63.5 | D20: {=LOOKUP(2,1/('Deliverables Sheet'!T60:T65<>0),'Deliverables Sheet'!T60:T65)} -> 26.75 | E20: {=LOOKUP(2,1/('Deliverables Sheet'!U60:U65<>0),'Deliverables Sheet'!U60:U65)} -> 36.75 | M20: 36
A22: ='Main Sheet'!A22 -> 9065 | B22: ='Main Sheet'!B22 -> Cooltranz stage 4 | C22: {=LOOKUP(2,1/('Deliverables Sheet'!S67:S72<>0),'Deliverables Sheet'!S67:S72)} -> 160.82 | D22: {=LOOKUP(2,1/('Deliverables Sheet'!T67:T72<>0),'Deliverables Sheet'!T67:T72)} -> #N/A | E22: {=LOOKUP(2,1/('Deliverables Sheet'!U67:U72<>0),'Deliverables Sheet'!U67:U72)} -> 160.82 | M22: 20 | N22: 80 | O22: 60
A24: ='Main Sheet'!A24 -> 9259 | B24: ='Main Sheet'!B24 -> Andrew Reeve Stage 2 | E24: {=LOOKUP(2,1/('Deliverables Sheet'!U69:U74<>0),'Deliverables Sheet'!U69:U74)} -> #N/A | M24: 188 | N24: 282
A26: ='Main Sheet'!A26 -> 8352 | B26: ='Main Sheet'!B26 -> 5 Sanscrit Place | C26: {=LOOKUP(2,1/('Deliverables Sheet'!S81:S86<>0),'Deliverables Sheet'!S81:S86)} -> 139.07 | D26: {=LOOKUP(2,1/('Deliverables Sheet'!T81:T86<>0),'Deliverables Sheet'!T81:T86)} -> 143.25 | E26: {=LOOKUP(2,1/('Deliverables Sheet'!U81:U86<>0),'Deliverables Sheet'!U81:U86)} -> -4.18 | M26: 48
A28: ='Main Sheet'!A28 -> 8234 | B28: ='Main Sheet'!B28 -> Melhuish House | C28: {=LOOKUP(2,1/('Deliverables Sheet'!S88:S93<>0),'Deliverables Sheet'!S88:S93)} -> 231.75 | D28: {=LOOKUP(2,1/('Deliverables Sheet'!T88:T93<>0),'Deliverables Sheet'!T88:T93)} -> 148.5 | E28: {=LOOKUP(2,1/('Deliverables Sheet'!U88:U93<>0),'Deliverables Sheet'!U88:U93)} -> 83.25 | M28: 32
A30: ='Main Sheet'!A30 -> 8214 | B30: ='Main Sheet'!B30 -> 6 Tiroroa Lane | C30: {=LOOKUP(2,1/('Deliverables Sheet'!S95:S100<>0),'Deliverables Sheet'!S95:S100)} -> 147.9 | D30: {=LOOKUP(2,1/('Deliverables Sheet'!T95:T100<>0),'Deliverables Sheet'!T95:T100)} -> 5 | E30: {=LOOKUP(2,1/('Deliverables Sheet'!U95:U100<>0),'Deliverables Sheet'!U95:U100)} -> 142.9 | N30: 48 | O30: 16 | P30: 64
A32: ='Main Sheet'!A32 -> 6792 | B32: ='Main Sheet'!B32 -> Major Hornbrook | C32: {=LOOKUP(2,1/('Deliverables Sheet'!S102:S107<>0),'Deliverables Sheet'!S102:S107)} -> 208.2 | D32: {=LOOKUP(2,1/('Deliverables Sheet'!T102:T107<>0),'Deliverables Sheet'!T102:T107)} -> 317.25 | E32: {=LOOKUP(2,1/('Deliverables Sheet'!U102:U107<>0),'Deliverables Sheet'!U102:U107)} -> -109.05
A34: ='Main Sheet'!A34 -> 8840 | B34: ='Main Sheet'!B34 -> Inline Architecture | C34: {=LOOKUP(2,1/('Deliverables Sheet'!S109:S114<>0),'Deliverables Sheet'!S109:S114)} -> 316.34 | D34: {=LOOKUP(2,1/('Deliverables Sheet'!T109:T114<>0),'Deliverables Sheet'!T109:T114)} -> 204.75 | E34: {=LOOKUP(2,1/('Deliverables Sheet'!U109:U114<>0),'Deliverables Sheet'!U109:U114)} -> 111.59 | M34: 130
A36: ='Main Sheet'!A36 -> 8769 | B36: ='Main Sheet'!B36 -> Percival Bach | C36: {=LOOKUP(2,1/('Deliverables Sheet'!S116:S121<>0),'Deliverables Sheet'!S116:S121)} -> #N/A | D36: {=LOOKUP(2,1/('Deliverables Sheet'!T116:T121<>0),'Deliverables Sheet'!T116:T121)} -> #N/A | E36: {=LOOKUP(2,1/('Deliverables Sheet'!U116:U121<>0),'Deliverables Sheet'!U116:U121)} -> #N/A | M36: 30 | N36: 50
A38: ='Main Sheet'!A38 -> 7901 | B38: ='Main Sheet'!B38 -> St Albans Street | C38: {=LOOKUP(2,1/('Deliverables Sheet'!S123:S128<>0),'Deliverables Sheet'!S123:S128)} -> 273.37 | D38: {=LOOKUP(2,1/('Deliverables Sheet'!T123:T128<>0),'Deliverables Sheet'!T123:T128)} -> #N/A | E38: {=LOOKUP(2,1/('Deliverables Sheet'!U123:U128<>0),'Deliverables Sheet'!U123:U128)} -> 273.37 | M38: 80 | N38: 40 | O38: 160
A40: ='Main Sheet'!A40 -> 8923 | B40: ='Main Sheet'!B40 -> 4 Perry St | C40: {=LOOKUP(2,1/('Deliverables Sheet'!S130:S135<>0),'Deliverables Sheet'!S130:S135)} -> 157 | D40: {=LOOKUP(2,1/('Deliverables Sheet'!T130:T135<>0),'Deliverables Sheet'!T130:T135)} -> 2 | E40: {=LOOKUP(2,1/('Deliverables Sheet'!U130:U135<>0),'Deliverables Sheet'!U130:U135)} -> 155 | F40: 60 | G40: 15 | H40: 90
A42: ='Main Sheet'!A42 -> 7864 | B42: ='Main Sheet'!B42 -> Ryans House | C42: {=LOOKUP(2,1/('Deliverables Sheet'!S137:S142<>0),'Deliverables Sheet'!S137:S142)} -> 193.82 | D42: {=LOOKUP(2,1/('Deliverables Sheet'!T137:T142<>0),'Deliverables Sheet'!T137:T142)} -> 266.75 | E42: {=LOOKUP(2,1/('Deliverables Sheet'!U137:U142<>0),'Deliverables Sheet'!U137:U142)} -> -72.93
A44: ='Main Sheet'!A44 -> 7912 | B44: ='Main Sheet'!B44 -> 71A Fendalton Road | C44: {=LOOKUP(2,1/('Deliverables Sheet'!S144:S149<>0),'Deliverables Sheet'!S144:S149)} -> #N/A | D44: {=LOOKUP(2,1/('Deliverables Sheet'!T144:T149<>0),'Deliverables Sheet'!T144:T149)} -> #N/A | E44: {=LOOKUP(2,1/('Deliverables Sheet'!U144:U149<>0),'Deliverables Sheet'!U144:U149)} -> #N/A | F44: 80 | N44: 40 | O44: 300 | P44: 150 | Q44: 150
A46: ='Main Sheet'!A46 -> 8360 | B46: ='Main Sheet'!B46 -> Dixon House | C46: {=LOOKUP(2,1/('Deliverables Sheet'!S151:S156<>0),'Deliverables Sheet'!S151:S156)} -> 210.6 | D46: {=LOOKUP(2,1/('Deliverables Sheet'!T151:T156<>0),'Deliverables Sheet'!T151:T156)} -> 260.75 | E46: {=LOOKUP(2,1/('Deliverables Sheet'!U151:U156<>0),'Deliverables Sheet'!U151:U156)} -> -50.15
A48: ='Main Sheet'!A48 -> 8337 | B48: ='Main Sheet'!B48 -> Waimak Dairys | C48: {=LOOKUP(2,1/('Deliverables Sheet'!S158:S163<>0),'Deliverables Sheet'!S158:S163)} -> 110.44 | D48: {=LOOKUP(2,1/('Deliverables Sheet'!T158:T163<>0),'Deliverables Sheet'!T158:T163)} -> 44.75 | E48: {=LOOKUP(2,1/('Deliverables Sheet'!U158:U163<>0),'Deliverables Sheet'!U158:U163)} -> 65.69 | M48: 16 | N48: 32
A50: ='Main Sheet'!A50 -> 9240 | B50: ='Main Sheet'!B50 -> Daves Twizel Shack | C50: {=LOOKUP(2,1/('Deliverables Sheet'!S165:S170<>0),'Deliverables Sheet'!S165:S170)} -> #N/A | D50: {=LOOKUP(2,1/('Deliverables Sheet'!T165:T170<>0),'Deliverables Sheet'!T165:T170)} -> #N/A | E50: {=LOOKUP(2,1/('Deliverables Sheet'!U165:U170<>0),'Deliverables Sheet'!U165:U170)} -> #N/A | M50: 16 | N50: 40
A52: ='Main Sheet'!A52 -> 7428 | B52: ='Main Sheet'!B52 -> FAB Pegasus Lakeside | C52: {=LOOKUP(2,1/('Deliverables Sheet'!S172:S177<>0),'Deliverables Sheet'!S172:S177)} -> 659.73 | D52: {=LOOKUP(2,1/('Deliverables Sheet'!T172:T177<>0),'Deliverables Sheet'!T172:T177)} -> 304.75 | E52: {=LOOKUP(2,1/('Deliverables Sheet'!U172:U177<>0),'Deliverables Sheet'!U172:U177)} -> 354.98 | M52: 80 | N52: 80 | O52: 180
A54: ='Main Sheet'!A54 -> 9351 | B54: ='Main Sheet'!B54 -> Harewood Golf Club | C54: {=LOOKUP(2,1/('Deliverables Sheet'!S179:S184<>0),'Deliverables Sheet'!S179:S184)} -> 125.17 | D54: {=LOOKUP(2,1/('Deliverables Sheet'!T179:T184<>0),'Deliverables Sheet'!T179:T184)} -> 11.25 | E54: {=LOOKUP(2,1/('Deliverables Sheet'!U179:U184<>0),'Deliverables Sheet'!U179:U184)} -> 113.92 | L54: 16 | M54: 32 | N54: 65
A56: ='Main Sheet'!A56 -> 7429 | B56: ='Main Sheet'!B56 -> Taggart House | C56: {=LOOKUP(2,1/('Deliverables Sheet'!S186:S191<>0),'Deliverables Sheet'!S186:S191)} -> 130.62 | D56: {=LOOKUP(2,1/('Deliverables Sheet'!T186:T191<>0),'Deliverables Sheet'!T186:T191)} -> 32.25 | E56: {=LOOKUP(2,1/('Deliverables Sheet'!U186:U191<>0),'Deliverables Sheet'!U186:U191)} -> 98.37 | M56: 16 | N56: 70
A58: ='Main Sheet'!A58 -> 9508 | B58: ='Main Sheet'!B58 -> St Barnabas Church | C58: {=LOOKUP(2,1/('Deliverables Sheet'!S193:S198<>0),'Deliverables Sheet'!S193:S198)} -> #N/A | D58: {=LOOKUP(2,1/('Deliverables Sheet'!T193:T198<>0),'Deliverables Sheet'!T193:T198)} -> #N/A | E58: {=LOOKUP(2,1/('Deliverables Sheet'!U193:U198<>0),'Deliverables Sheet'!U193:U198)} -> #N/A | O58: 52 | P58: 13 | Q58: 69
A60: ='Main Sheet'!A60 -> 0 | B60: ='Main Sheet'!B60 -> 0 | C60: {=LOOKUP(2,1/('Deliverables Sheet'!S200:S205<>0),'Deliverables Sheet'!S200:S205)} -> #N/A | D60: {=LOOKUP(2,1/('Deliverables Sheet'!T200:T205<>0),'Deliverables Sheet'!T200:T205)} -> #N/A | E60: {=LOOKUP(2,1/('Deliverables Sheet'!U200:U205<>0),'Deliverables Sheet'!U200:U205)} -> #N/A
A62: ='Main Sheet'!A62 -> 0 | B62: ='Main Sheet'!B62 -> Contracting | C62: {=LOOKUP(2,1/('Deliverables Sheet'!S207:S212<>0),'Deliverables Sheet'!S207:S212)} -> #N/A | D62: {=LOOKUP(2,1/('Deliverables Sheet'!T207:T212<>0),'Deliverables Sheet'!T207:T212)} -> #N/A | E62: {=LOOKUP(2,1/('Deliverables Sheet'!U207:U212<>0),'Deliverables Sheet'!U207:U212)} -> #N/A
A64: ='Main Sheet'!A64 -> 8946 | B64: ='Main Sheet'!B64 -> Westcoast Vaults | C64: {=LOOKUP(2,1/('Deliverables Sheet'!S214:S219<>0),'Deliverables Sheet'!S214:S219)} -> 358.86 | D64: {=LOOKUP(2,1/('Deliverables Sheet'!T214:T219<>0),'Deliverables Sheet'!T214:T219)} -> #N/A | E64: {=LOOKUP(2,1/('Deliverables Sheet'!U214:U219<>0),'Deliverables Sheet'!U214:U219)} -> 358.86 | N64: 143 | P64: 215
A66: ='Main Sheet'!A66 -> 8308 | B66: ='Main Sheet'!B66 -> Roydvale | C66: {=LOOKUP(2,1/('Deliverables Sheet'!S221:S226<>0),'Deliverables Sheet'!S221:S226)} -> 2312.68 | D66: {=LOOKUP(2,1/('Deliverables Sheet'!T221:T226<>0),'Deliverables Sheet'!T221:T226)} -> 1014.25 | E66: {=LOOKUP(2,1/('Deliverables Sheet'!U221:U226<>0),'Deliverables Sheet'!U221:U226)} -> 1298.43 | M66: 320 | N66: 250 | O66: 250 | P66: 240 | Q66: 80
B70: Total Hours | C70: =C3+C71+C72 -> #N/A | D70: =D3+D71+D72 -> #N/A | E70: =E3+E71+E72 -> #N/A | F70: =F3+F71+F72 -> 640 | G70: =G3+G71+G72 -> 715 | H70: =H3+H71+H72 -> 790 | I70: =I3+I71+I72 -> 700 | J70: =J3+J71+J72 -> 700 | ... Q70: =Q3+Q71+Q72 -> 650
B71: Residential Hours | C71: =SUM(C26:C46) -> #N/A | D71: =SUM(D26:D46) -> #N/A | E71: =SUM(E26:E46) -> #N/A | F71: =SUM(F26:F46) -> 140 | G71: =SUM(G26:G46) -> 15 | H71: =SUM(H26:H46) -> 90 | I71: =SUM(I26:I66) -> 0 | J71: =SUM(J26:J66) -> 0 | K71: =SUM(K26:K66) -> 0 | L71: =SUM(L26:L66) -> 16 | M71: =SUM(M26:M66) -> 800 | N71: =SUM(N26:N66) -> 858 | O71: =SUM(O26:O46) -> 476 | P71: =SUM(P26:P46) -> 214 | Q71: =SUM(Q26:Q46) -> 150
B72: Commercial Hours | C72: =SUM(C4:C24) -> 4490.26 | D72: =SUM(D4:D24) -> #N/A | E72: =SUM(E4:E24) -> #N/A | F72: =SUM(F4:F24) -> 0 | G72: =SUM(G4:G24) -> 0 | H72: =SUM(H4:H24) -> 0 | I72: =SUM(I4:I24) -> 0 | J72: =SUM(J4:J24) -> 0 | ... Q72: =SUM(Q4:Q24) -> 0
B73: Hours Available | F73: =F77*F76*8*0.8 -> 1488 | G73: =G77*G76*8*0.8 -> 2112 | H73: =H77*H76*8*0.8 -> 1984 | I73: =I77*I76*8*0.8 -> 1884.8 | J73: =J77*J76*8*0.8 -> 1948.8 | K73: =K77*K76*8*0.8 -> 2083.2 | L73: =L77*L76*8*0.8 -> 2604.8 | M73: =M77*M76*8*0.8 -> 2486.4 | ... Q73: =Q77*Q76*8*0.8 -> 1478.4
B74: Balance Hours | F74: =F70-F73 -> -848 | G74: =G70-G73 -> -1397 | H74: =H70-H73 -> -1194 | I74: =I70-I73 -> -1184.8 | J74: =J70-J73 -> -1248.8 | K74: =K70-K73 -> -1383.2 | L74: =L70-L73 -> -1888.8 | M74: =M70-M73 -> 33.6 | ... Q74: =Q70-Q73 -> -828.4
...

Sheet Note Cam (To Do)
A2: Cams Notes
A3: Koawa:
A4: New job meeting set up for 8am wednesday - Tim, Dylan, VD, Cam - Perhaps bring in Jacob once back from leave??
A5: Tray shop drawings into engineers - waiting on geoff to send back multidraw drawings.
A6: DB dates for sites (livening 11 July)
A7: Confirm Warrenties agreement
A8: Go to tech submissions meeting on Wednesday 12th March
A9: Start getting orders in, (so far PDL gear ordered through rads) need to look at lights beign ordered that we can - confirm process.
A12: Tru Hire:
A13: Temp should be on Monday morning 14.04.25
A14: Craig would like an export/list for me please mate that captures all of the costs to date from you guys and ILS?
A15: Riccarton High:
... A50: Comes up with hours tracking solution

Sheet Note Tom (To Do) 
A2: Tom's Notes:
A38: Other:
A39: Comes up with hours tracking solution

Sheet Deliverables_RR_Test_Sheet (2)
A1: Updated Job Spreadsheet
A2: Job Number | B2: Job Name | C2: Week | D2: Quoted Price | E2: Claim to date | F2: Remaining to claim | G2: % Claim remaining | H2: Total quoted cost | I2: Total actual cost | J2: Quoted material cost | K2: Actual material cost | L2: Material cost remaining | M2: Material % remaining | N2: Estimated % of materials recieved | O2: Contractor Quoted Cost | P2: Contractor Actual Cost | Q2: Contractor Balance | R2: Quoted labour cost | S2: Actual labour cost | T2: Labour cost remaining | U2: Labour cost % remaining | V2: Quoted labour hours | W2: Actual labour hours | X2: Labour hours remaining | Y2: Labour hour % remaining | Z2: Estimated % of job complete | AA2: GP $ Per Hour | AB2: Quoted GP $ Per Hour | AC2: Margin to date | AD2: Quoted margin
AK3: Hours calcs | AL3: Materials calcs
A4: ='Main Sheet'!A4 -> 7658 | B4: ='Main Sheet'!B4 -> Charity Hospital | C4: Start of month | D4: 1914143.5 | E4: 1667392.4 | F4: =D4-E4 -> 246751.12 | G4: =F4/D4 -> 0.12890941 | H4: 1675578 | I4: 1406264.8 | J4: =SUM(H4-(R4+O4)) -> 1511021.4 | K4: =SUM(I4-(S4+P4)) -> 1215391.4 | L4: =J4-K4 -> 295630 | M4: =L4/J4 -> 0.19564911 | O4: 5 | P4: 4 | Q4: =O4-P4 -> 1 | R4: 164551.54 | S4: 190869.33 | T4: =R4-S4 -> -26317.79 | U4: =T4/R4 -> -0.15993646 | V4: 3296.1 | W4: 4599 | X4: =V4-W4 -> -1302.9 | Y4: =X4/V4 -> -0.39528534 | AA4: =(E4-K4-S4)/W4 -> 56.780087 | AB4: =(D4-J4-R4)/V4 -> 72.37964 | AC4: =(E4-K4-S4)/E4 -> 0.15661078 | AD4: =SUM(D4-H4)/D4 -> 0.12463304 | AG4: Hours calc for monthly claims | AH4: =AK9 -> -4599 | AK4: =SUM(W5-W4) -> 415.49 | AL4: =SUM(K5-K4) -> 48650.89
C5: Week 1 | D5: 1922479.9 | E5: 1667392.4 | F5: =D5-E5 -> 255087.52 | G5: =F5/D5 -> 0.1326867 | H5: 1681960.6 | I5: 1474477.1 | J5: =SUM(H5-R5) -> 1516687.4 | K5: =SUM(I5-S5) -> 1264042.3 | L5: =J5-K5 -> 252645.09 | M5: =L5/J5 -> 0.1665769 | R5: 165273.18 | S5: 210434.8 | T5: =R5-S5 -> -45161.62 | U5: =T5/R5 -> -0.27325438 | V5: 3312.1 | W5: 5014.49 | X5: =V5-W5 -> -1702.39 | Y5: =X5/V5 -> -0.51399112 | AA5: =(E5-K5-S5)/W5 -> 38.471561 | AB5: =(D5-J5-R5)/V5 -> 72.618372 | AC5: =(E5-K5-S5)/E5 -> 0.11569878 | AD5: =SUM(D5-H5)/D5 -> 0.12510888 | AG5: Materials calc for monthly claims | AH5: =AL9 -> -1215391.4 | AK5: =SUM(W6-W5) -> 134.5 | AL5: =SUM(K6-K5) -> 24752.67
C6: Week 2 | D6: 1922479.9 | E6: 1667392.4 | F6: =D6-E6 -> 255087.52 | G6: =F6/D6 -> 0.1326867 | H6: 1681960.6 | I6: 1505572.2 | J6: =SUM(H6-R6) -> 1516687.4 | K6: =SUM(I6-S6) -> 1288795 | L6: =J6-K6 -> 227892.42 | M6: =L6/J6 -> 0.15025668 | N6: 0.9 | R6: 165273.18 | S6: 216777.2 | T6: =R6-S6 -> -51504.02 | U6: =T6/R6 -> -0.31162963 | V6: 3312.1 | W6: 5148.99 | X6: =V6-W6 -> -1836.89 | Y6: =X6/V6 -> -0.5545998 | Z6: 0.9 | AA6: =(E6-K6-S6)/W6 -> 31.42756 | AB6: =(D6-J6-R6)/V6 -> 72.618372 | AC6: =(E6-K6-S6)/E6 -> 0.097049855 | AD6: =SUM(D6-H6)/D6 -> 0.12510888 | AK6: =SUM(W7-W6) -> -5148.99 | AL6: =SUM(K7-K6) -> -1288795
C7: Week 3 | F7: =D7-E7 -> 0 | G7: =F7/D7 -> #DIV/0! | J7: =SUM(H7-R7) -> 0 | K7: =SUM(I7-S7) -> 0 | L7: =J7-K7 -> 0 | M7: =L7/J7 -> #DIV/0! | T7: =R7-S7 -> 0 | U7: =T7/R7 -> #DIV/0! | X7: =V7-W7 -> 0 | Y7: =X7/V7 -> #DIV/0! | AA7: =(E7-K7-S7)/W7 -> #DIV/0! | AB7: =(D7-J7-R7)/V7 -> #DIV/0! | AC7: =(E7-K7-S7)/E7 -> #DIV/0! | AD7: =SUM(D7-H7)/D7 -> #DIV/0! | AG7: Estimated months claim | AH7: 0 | AK7: =SUM(W8-W7) -> 0 | AL7: =SUM(K8-K7) -> 0
C8: Week 4 | F8: =D8-E8 -> 0 | G8: =F8/D8 -> #DIV/0! | J8: =SUM(H8-R8) -> 0 | K8: =SUM(I8-S8) -> 0 | L8: =J8-K8 -> 0 | M8: =L8/J8 -> #DIV/0! | T8: =R8-S8 -> 0 | U8: =T8/R8 -> #DIV/0! | X8: =V8-W8 -> 0 | Y8: =X8/V8 -> #DIV/0! | AA8: =(E8-K8-S8)/W8 -> #DIV/0! | AB8: =(D8-J8-R8)/V8 -> #DIV/0! | AC8: =(E8-K8-S8)/E8 -> #DIV/0! | AD8: =SUM(D8-H8)/D8 -> #DIV/0! | AK8: =SUM(W9-W8) -> 0 | AL8: =SUM(K9-K8) -> 0
C9: Week 5 | F9: =D9-E9 -> 0 | G9: =F9/D9 -> #DIV/0! | J9: =SUM(H9-R9) -> 0 | K9: =SUM(I9-S9) -> 0 | L9: =J9-K9 -> 0 | M9: =L9/J9 -> #DIV/0! | T9: =R9-S9 -> 0 | U9: =T9/R9 -> #DIV/0! | X9: =V9-W9 -> 0 | Y9: =X9/V9 -> #DIV/0! | AA9: =(E9-K9-S9)/W9 -> #DIV/0! | AB9: =(D9-J9-R9)/V9 -> #DIV/0! | AC9: =(E9-K9-S9)/E9 -> #DIV/0! | AD9: =SUM(D9-H9)/D9 -> #DIV/0! | AK9: =SUM(AK4,AK5,AK6,AK7,AK8) -> -4599 | AL9: =SUM(AL4,AL5,AL6,AL7,AL8) -> -1215391.4
A11: ='Main Sheet'!A6 -> 8142 | B11: ='Main Sheet'!B6 -> Fisher Developements | C11: Start of month | D11: 381671.63 | E11: 144223.4 | F11: =D11-E11 -> 237448.23 | G11: =F11/D11 -> 0.62212701 | H11: 329257.09 | I11: 168819.17 | J11: =SUM(H11-R11) -> 288248.16 | K11: =SUM(I11-S11) -> 158648.53 | L11: =J11-K11 -> 129599.63 | M11: =L11/J11 -> 0.4496113 | R11: 41008.93 | S11: 10170.64 | T11: =R11-S11 -> 30838.29 | U11: =T11/R11 -> 0.75198963 | V11: 821.2 | W11: 241 | X11: =V11-W11 -> 580.2 | Y11: =X11/V11 -> 0.70652703 | AA11: =(E11-K11-S11)/W11 -> -102.05714 | AB11: =(D11-J11-R11)/V11 -> 63.826766 | AC11: =(E11-K11-S11)/E11 -> -0.17053939 | AD11: =SUM(D11-H11)/D11 -> 0.13732889 | AG11: Hours calc for monthly claims | AH11: =AK16 -> -241 | AK11: =SUM(W12-W11) -> 96.25 | AL11: =SUM(K12-K11) -> 30474.42
C12: Week 1 | D12: 382219.49 | E12: 240065.55 | F12: =D12-E12 -> 142153.94 | G12: =F12/D12 -> 0.37191704 | H12: 329585.81 | I12: 202828.2 | J12: =SUM(H12-R12) -> 288352.94 | K12: =SUM(I12-S12) -> 189122.95 | L12: =J12-K12 -> 99229.99 | M12: =L12/J12 -> 0.34412685 | R12: 41232.87 | S12: 13705.25 | T12: =R12-S12 -> 27527.62 | U12: =T12/R12 -> 0.66761348 | V12: 825.68 | W12: 337.25 | X12: =V12-W12 -> 488.43 | Y12: =X12/V12 -> 0.59154878 | AA12: =(E12-K12-S12)/W12 -> 110.41468 | AB12: =(D12-J12-R12)/V12 -> 63.745858 | AC12: =(E12-K12-S12)/E12 -> 0.15511326 | AD12: =SUM(D12-H12)/D12 -> 0.13770538 | AG12: Materials calc for monthly claims | AH12: =AL16 -> -158648.53 | AK12: =SUM(W13-W12) -> 101.75 | AL12: =SUM(K13-K12) -> 7119.32
C13: Week 2 | D13: 382219.49 | E13: 240065.55 | F13: =D13-E13 -> 142153.94 | G13: =F13/D13 -> 0.37191704 | H13: 329585.81 | I13: 213730.54 | J13: =SUM(H13-R13) -> 288352.94 | K13: =SUM(I13-S13) -> 196242.27 | L13: =J13-K13 -> 92110.67 | M13: =L13/J13 -> 0.31943725 | R13: 41232.87 | S13: 17488.27 | T13: =R13-S13 -> 23744.6 | U13: =T13/R13 -> 0.57586581 | V13: 825.68 | W13: 439 | X13: =V13-W13 -> 386.68 | Y13: =X13/V13 -> 0.46831702 | AA13: =(E13-K13-S13)/W13 -> 59.988633 | AB13: =(D13-J13-R13)/V13 -> 63.745858 | AC13: =(E13-K13-S13)/E13 -> 0.10969925 | AD13: =SUM(D13-H13)/D13 -> 0.13770538 | AK13: =SUM(W14-W13) -> -439 | AL13: =SUM(K14-K13) -> 23228
C14: Week 3 | D14: 383409.63 | E14: 240065.55 | F14: =D14-E14 -> 143344.08 | G14: =F14/D14 -> 0.37386667 | H14: 330537 | I14: 246817.11 | J14: 289155.03 | K14: 219470.27 | L14: =J14-K14 -> 69684.76 | M14: =L14/J14 -> 0.24099446 | N14: 0.75 | T14: =R14-S14 -> 0 | U14: =T14/R14 -> #DIV/0! | X14: =V14-W14 -> 0 | Y14: =X14/V14 -> #DIV/0! | AA14: =(E14-K14-S14)/W14 -> #DIV/0! | AB14: =(D16-J14-R14)/V14 -> #DIV/0! | AC14: =(E14-K14-S14)/E14 -> 0.085790235 | AD14: =SUM(D16-H14)/D16 -> 0.13790115 | AG14: Estimated months claim | AH14: 0 | AK14: =SUM(W15-W14) -> 0 | AL14: =SUM(K15-K14) -> -219470.27
C15: Week 4 | D15: 383409.63 | F15: =D15-E15 -> 383409.63 | G15: =F15/D15 -> 1 | J15: =SUM(H15-R15) -> 0 | K15: =SUM(I15-S15) -> 0 | L15: =J15-K15 -> 0 | M15: =L15/J15 -> #DIV/0! | T15: =R15-S15 -> 0 | U15: =T15/R15 -> #DIV/0! | X15: =V15-W15 -> 0 | Y15: =X15/V15 -> #DIV/0! | AA15: =(E15-K15-S15)/W15 -> #DIV/0! | AB15: =(D15-J15-R15)/V15 -> #DIV/0! | AC15: =(E15-K15-S15)/E15 -> #DIV/0! | AD15: =SUM(D15-H15)/D15 -> 1 | AK15: =SUM(W16-W15) -> 0 | AL15: =SUM(K16-K15) -> 0
C16: Week 5 | D16: 383409.63 | F16: =D16-E16 -> 383409.63 | G16: =F16/D16 -> 1 | J16: =SUM(H16-R16) -> 0 | K16: =SUM(I16-S16) -> 0 | L16: =J16-K16 -> 0 | M16: =L16/J16 -> #DIV/0! | N16: 0.55 | T16: =R16-S16 -> 0 | U16: =T16/R16 -> #DIV/0! | X16: =V16-W16 -> 0 | Y16: =X16/V16 -> #DIV/0! | Z16: 0.35 | AA16: =(E16-K16-S16)/W16 -> #DIV/0! | AB16: =(#REF!-J16-R16)/V16 -> #REF! | AC16: =(E16-K16-S16)/E16 -> #DIV/0! | AD16: =SUM(#REF!-H16)/#REF! -> #REF! | AK16: =SUM(AK11,AK12,AK13,AK14,AK15) -> -241 | AL16: =SUM(AL11,AL12,AL13,AL14,AL15) -> -158648.53
A18: 7104 | B18: ='Main Sheet'!B8 -> 3 Innovation Road | C18: Start of month | D18: 449818.08 | E18: 246538.95 | F18: =D18-E18 -> 203279.13 | G18: =F18/D18 -> 0.45191409 | H18: 329858.1 | I18: 251921.97 | J18: =SUM(H18-R18) -> 255282.19 | K18: =SUM(I18-S18) -> 219103.38 | L18: =J18-K18 -> 36178.81 | M18: =L18/J18 -> 0.14172085 | N18: 0 | R18: 74575.91 | S18: 32818.59 | T18: =R18-S18 -> 41757.32 | U18: =T18/R18 -> 0.55993041 | V18: 1493.36 | W18: 799.5 | X18: =V18-W18 -> 693.86 | Y18: =X18/V18 -> 0.4646301 | Z18: 0 | AA18: =(E18-K18-S18)/W18 -> -6.7329831 | AB18: =(D18-J18-R18)/V18 -> 80.328909 | AC18: =(E18-K18-S18)/E18 -> -0.021834359 | AD18: =SUM(D18-H18)/D18 -> 0.26668555 | AG18: Hours calc for monthly claims | AH18: =AK23 -> -799.5 | AK18: =SUM(W19-W18) -> 57.75 | AL18: =SUM(K19-K18) -> -918.26
C19: Week 1 | D19: 449818.08 | E19: 364039.73 | F19: =D19-E19 -> 85778.35 | G19: =F19/D19 -> 0.19069565 | H19: 329858.1 | I19: 253347.64 | J19: =SUM(H19-R19) -> 255282.19 | K19: =SUM(I19-S19) -> 218185.12 | L19: =J19-K19 -> 37097.07 | M19: =L19/J19 -> 0.14531789 | R19: 74575.91 | S19: 35162.52 | T19: =R19-S19 -> 39413.39 | U19: =T19/R19 -> 0.52850029 | V19: 1493.36 | W19: 857.25 | X19: =V19-W19 -> 636.11 | Y19: =X19/V19 -> 0.42595891 | Z19: 0.1 | AA19: =(E19-K19-S19)/W19 -> 129.12463 | AB19: =(D19-J19-R19)/V19 -> 80.328909 | AC19: =(E19-K19-S19)/E19 -> 0.30406596 | AD19: =SUM(D19-H19)/D19 -> 0.26668555 | AG19: Materials calc for monthly claims | AH19: =AL23 -> -219103.38 | AK19: =SUM(W20-W19) -> 93.75 | AL19: =SUM(K20-K19) -> 5813.69
C20: Week 2 | D20: 449818.08 | E20: 364039.73 | F20: =D20-E20 -> 85778.35 | G20: =F20/D20 -> 0.19069565 | H20: 329858.1 | I20: 262942.02 | J20: =SUM(H20-R20) -> 255282.19 | K20: =SUM(I20-S20) -> 223998.81 | L20: =J20-K20 -> 31283.38 | M20: =L20/J20 -> 0.12254431 | R20: 74575.91 | S20: 38943.21 | T20: =R20-S20 -> 35632.7 | U20: =T20/R20 -> 0.47780443 | V20: 1493.36 | W20: 951 | X20: =V20-W20 -> 542.36 | Y20: =X20/V20 -> 0.36318101 | Z20: 0.15 | AA20: =(E20-K20-S20)/W20 -> 106.30674 | AB20: =(D20-J20-R20)/V20 -> 80.328909 | AC20: =(E20-K20-S20)/E20 -> 0.27771065 | AD20: =SUM(D20-H20)/D20 -> 0.26668555 | AK20: =SUM(W21-W20) -> -951 | AL20: =SUM(K21-K20) -> -223998.81
C21: Week 3 | F21: =D21-E21 -> 0 | G21: =F21/D21 -> #DIV/0! | J21: =SUM(H21-R21) -> 0 | K21: =SUM(I21-S21) -> 0 | L21: =J21-K21 -> 0 | M21: =L21/J21 -> #DIV/0! | T21: =R21-S21 -> 0 | U21: =T21/R21 -> #DIV/0! | X21: =V21-W21 -> 0 | Y21: =X21/V21 -> #DIV/0! | Z21: 0.03 | AA21: =(E21-K21-S21)/W21 -> #DIV/0! | AB21: =(D21-J21-R21)/V21 -> #DIV/0! | AC21: =(E21-K21-S21)/E21 -> #DIV/0! | AD21: =SUM(D21-H21)/D21 -> #DIV/0! | AG21: Estimated months claim | AH21: 0 | AK21: =SUM(W22-W21) -> 0 | AL21: =SUM(K22-K21) -> 0
C22: Week 4 | F22: =D22-E22 -> 0 | G22: =F22/D22 -> #DIV/0! | J22: =SUM(H22-R22) -> 0 | K22: =SUM(I22-S22) -> 0 | L22: =J22-K22 -> 0 | M22: =L22/J22 -> #DIV/0! | T22: =R22-S22 -> 0 | U22: =T22/R22 -> #DIV/0! | X22: =V22-W22 -> 0 | Y22: =X22/V22 -> #DIV/0! | Z22: 0.03 | AA22: =(E22-K22-S22)/W22 -> #DIV/0! | AB22: =(D22-J22-R22)/V22 -> #DIV/0! | AC22: =(E22-K22-S22)/E22 -> #DIV/0! | AD22: =SUM(D22-H22)/D22 -> #DIV/0! | AK22: =SUM(W23-W22) -> 0 | AL22: =SUM(K23-K22) -> 0
C23: Week 5 | F23: =D23-E23 -> 0 | G23: =F23/D23 -> #DIV/0! | J23: =SUM(H23-R23) -> 0 | K23: =SUM(I23-S23) -> 0 | L23: =J23-K23 -> 0 | M23: =L23/J23 -> #DIV/0! | N23: 0.9 | T23: =R23-S23 -> 0 | U23: =T23/R23 -> #DIV/0! | X23: =V23-W23 -> 0 | Y23: =X23/V23 -> #DIV/0! | Z23: 0.65 | AA23: =(E23-K23-S23)/W23 -> #DIV/0! | AB23: =(D23-J23-R23)/V23 -> #DIV/0! | AC23: =(E23-K23-S23)/E23 -> #DIV/0! | AD23: =SUM(D23-H23)/D23 -> #DIV/0! | AK23: =SUM(AK18,AK19,AK20,AK21,AK22) -> -799.5 | AL23: =SUM(AL18,AL19,AL20,AL21,AL22) -> -219103.38
A25: ='Main Sheet'!A10 -> 8127 | B25: ='Main Sheet'!B10 -> Rolly Autowash | C25: Start of month | D25: 38856.96 | E25: 0 | F25: =D25-E25 -> 38856.96 | G25: =F25/D25 -> 1 | H25: 27050.88 | I25: 1129.12 | J25: =SUM(H25-R25) -> 16492.08 | K25: =SUM(I25-S25) -> 1129.12 | L25: =J25-K25 -> 15362.96 | M25: =L25/J25 -> 0.93153562 | N25: 0 | R25: 10558.8 | S25: 0 | T25: =R25-S25 -> 10558.8 | U25: =T25/R25 -> 1 | V25: 213 | W25: 0 | X25: =V25-W25 -> 213 | Y25: =X25/V25 -> 1 | Z25: 0 | AA25: =(E25-K25-S25)/W25 -> #DIV/0! | AB25: =(D25-J25-R25)/V25 -> 55.427606 | AC25: =(E25-K25-S25)/E25 -> #DIV/0! | AD25: =SUM(D25-H25)/D25 -> 0.30383437 | AG25: Hours calc for monthly claims | AH25: =AK30 -> 0 | AK25: =SUM(W26-W25) -> 9.25 | AL25: =SUM(K26-K25) -> 5779.58
C26: Week 1 | D26: 38856.96 | E26: 0 | F26: =D26-E26 -> 38856.96 | G26: =F26/D26 -> 1 | H26: 27050.88 | I26: 7293.59 | J26: =SUM(H26-R26) -> 16492.08 | K26: =SUM(I26-S26) -> 6908.7 | L26: =J26-K26 -> 9583.38 | M26: =L26/J26 -> 0.58108983 | N26: 0 | R26: 10558.8 | S26: 384.89 | T26: =R26-S26 -> 10173.91 | U26: =T26/R26 -> 0.96354794 | V26: 213.13 | W26: 9.25 | X26: =V26-W26 -> 203.88 | Y26: =X26/V26 -> 0.95659926 | Z26: 0 | AA26: =(E26-K26-S26)/W26 -> -788.49622 | AB26: =(D26-J26-R26)/V26 -> 55.393797 | AC26: =(E26-K26-S26)/E26 -> #DIV/0! | AD26: =SUM(D26-H26)/D26 -> 0.30383437 | AG26: Materials calc for monthly claims | AH26: =AL30 -> -1129.12 | AK26: =SUM(W27-W26) -> 101.75 | AL26: =SUM(K27-K26) -> 6796.13
C27: Week 2 | D27: 38856.96 | E27: 0 | F27: =D27-E27 -> 38856.96 | G27: =F27/D27 -> 1 | H27: 27050.88 | I27: 18431.21 | J27: =SUM(H27-R27) -> 16492.08 | K27: =SUM(I27-S27) -> 13704.83 | L27: =J27-K27 -> 2787.25 | M27: =L27/J27 -> 0.16900536 | N27: 0 | R27: 10558.8 | S27: 4726.38 | T27: =R27-S27 -> 5832.42 | U27: =T27/R27 -> 0.55237527 | V27: 213.13 | W27: 111 | X27: =V27-W27 -> 102.13 | Y27: =X27/V27 -> 0.4791911 | Z27: 0 | AA27: =(E27-K27-S27)/W27 -> -166.04694 | AB27: =(D27-J27-R27)/V27 -> 55.393797 | AC27: =(E27-K27-S27)/E27 -> #DIV/0! | AD27: =SUM(D27-H27)/D27 -> 0.30383437 | AK27: =SUM(W28-W27) -> -111 | AL27: =SUM(K28-K27) -> -13704.83
C28: Week 3 | E28: 0 | F28: =D28-E28 -> 0 | G28: =F28/D28 -> #DIV/0! | J28: =SUM(H28-R28) -> 0 | K28: =SUM(I28-S28) -> 0 | L28: =J28-K28 -> 0 | M28: =L28/J28 -> #DIV/0! | N28: 0 | S28: 0 | T28: =R28-S28 -> 0 | U28: =T28/R28 -> #DIV/0! | W28: 0 | X28: =V28-W28 -> 0 | Y28: =X28/V28 -> #DIV/0! | Z28: 0 | AA28: =(E28-K28-S28)/W28 -> #DIV/0! | AB28: =(D28-J28-R28)/V28 -> #DIV/0! | AC28: =(E28-K28-S28)/E28 -> #DIV/0! | AD28: =SUM(D28-H28)/D28 -> #DIV/0! | AG28: Estimated months claim | AH28: 0 | AK28: =SUM(W29-W28) -> 0 | AL28: =SUM(K29-K28) -> 0
C29: Week 4 | E29: 0 | F29: =D29-E29 -> 0 | G29: =F29/D29 -> #DIV/0! | J29: =SUM(H29-R29) -> 0 | K29: =SUM(I29-S29) -> 0 | L29: =J29-K29 -> 0 | M29: =L29/J29 -> #DIV/0! | N29: 0 | S29: 0 | T29: =R29-S29 -> 0 | U29: =T29/R29 -> #DIV/0! | W29: 0 | X29: =V29-W29 -> 0 | Y29: =X29/V29 -> #DIV/0! | Z29: 0 | AA29: =(E29-K29-S29)/W29 -> #DIV/0! | AB29: =(D29-J29-R29)/V29 -> #DIV/0! | AC29: =(E29-K29-S29)/E29 -> #DIV/0! | AD29: =SUM(D29-H29)/D29 -> #DIV/0! | AK29: =SUM(W30-W29) -> 0 | AL29: =SUM(K30-K29) -> 0
C30: Week 5 | E30: 0 | F30: =D30-E30 -> 0 | G30: =F30/D30 -> #DIV/0! | J30: =SUM(H30-R30) -> 0 | K30: =SUM(I30-S30) -> 0 | L30: =J30-K30 -> 0 | M30: =L30/J30 -> #DIV/0! | N30: 0 | S30: 0 | T30: =R30-S30 -> 0 | U30: =T30/R30 -> #DIV/0! | W30: 0 | X30: =V30-W30 -> 0 | Y30: =X30/V30 -> #DIV/0! | Z30: 0 | AA30: =(E30-K30-S30)/W30 -> #DIV/0! | AB30: =(D30-J30-R30)/V30 -> #DIV/0! | AC30: =(E30-K30-S30)/E30 -> #DIV/0! | AD30: =SUM(D30-H30)/D30 -> #DIV/0! | AK30: =SUM(AK25,AK26,AK27,AK28,AK29) -> 0 | AL30: =SUM(AL25,AL26,AL27,AL28,AL29) -> -1129.12
A32: ='Main Sheet'!A12 -> 8183 | B32: ='Main Sheet'!B12 -> Murney - 1 Freight Drive + 109 Iport | C32: Start of month | D32: 69191.71 | E32: 0 | F32: =D32-E32 -> 69191.71 | G32: =F32/D32 -> 1 | H32: 53243.87 | I32: 641.28 | J32: =SUM(H32-R32) -> 41588.94 | K32: =SUM(I32-S32) -> 171.84 | L32: =J32-K32 -> 41417.1 | M32: =L32/J32 -> 0.99586813 | R32: 11654.93 | S32: 469.44 | T32: =R32-S32 -> 11185.49 | U32: =T32/R32 -> 0.95972177 | V32: 233.59 | W32: 12.5 | X32: =V32-W32 -> 221.09 | Y32: =X32/V32 -> 0.94648744 | Z32: 0 | AA32: =(E32-K32-S32)/W32 -> -51.3024 | AB32: =(D32-J32-R32)/V32 -> 68.272786 | AC32: =(E32-K32-S32)/E32 -> #DIV/0! | AD32: =SUM(D32-H32)/D32 -> 0.23048773 | AG32: Hours calc for monthly claims | AH32: =AK37 -> -12.5 | AK32: =SUM(W33-W32) -> 4.5 | AL32: =SUM(K33-K32) -> 13.95
C33: Week 1 | D33: 69191.71 | E33: 1364.78 | F33: =D33-E33 -> 67826.93 | G33: =F33/D33 -> 0.98027538 | H33: 53243.87 | I33: 844.77 | J33: =SUM(H33-R33) -> 41588.94 | K33: =SUM(I33-S33) -> 185.79 | L33: =J33-K33 -> 41403.15 | M33: =L33/J33 -> 0.99553271 | R33: 11654.93 | S33: 658.98 | T33: =R33-S33 -> 10995.95 | U33: =T33/R33 -> 0.94345912 | V33: 233.59 | W33: 17 | X33: =V33-W33 -> 216.59 | Y33: =X33/V33 -> 0.92722291 | AA33: =(E33-K33-S33)/W33 -> 30.588824 | AB33: =(D33-J33-R33)/V33 -> 68.272786 | AC33: =(E33-K33-S33)/E33 -> 0.38102112 | AD33: =SUM(D33-H33)/D33 -> 0.23048773 | AG33: Materials calc for monthly claims | AH33: =AL37 -> -171.84 | AK33: =SUM(W34-W33) -> 3 | AL33: =SUM(K34-K33) -> 3907.37
C34: Week 2 | D34: 69191.71 | E34: 1364.78 | F34: =D34-E34 -> 67826.93 | G34: =F34/D34 -> 0.98027538 | H34: 53243.87 | I34: 4850.24 | J34: =SUM(H34-R34) -> 41588.94 | K34: =SUM(I34-S34) -> 4093.16 | L34: =J34-K34 -> 37495.78 | M34: =L34/J34 -> 0.90158056 | R34: 11654.93 | S34: 757.08 | T34: =R34-S34 -> 10897.85 | U34: =T34/R34 -> 0.93504208 | V34: 233.59 | W34: 20 | X34: =V34-W34 -> 213.59 | Y34: =X34/V34 -> 0.9143799 | AA34: =(E34-K34-S34)/W34 -> -174.273 | AB34: =(D34-J34-R34)/V34 -> 68.272786 | AC34: =(E34-K34-S34)/E34 -> -2.5538622 | AD34: =SUM(D34-H34)/D34 -> 0.23048773 | AK34: =SUM(W35-W34) -> -20 | AL34: =SUM(K35-K34) -> -4093.16
C35: Week 3 | F35: =D35-E35 -> 0 | G35: =F35/D35 -> #DIV/0! | J35: =SUM(H35-R35) -> 0 | K35: =SUM(I35-S35) -> 0 | L35: =J35-K35 -> 0 | M35: =L35/J35 -> #DIV/0! | T35: =R35-S35 -> 0 | U35: =T35/R35 -> #DIV/0! | X35: =V35-W35 -> 0 | Y35: =X35/V35 -> #DIV/0! | AA35: =(E35-K35-S35)/W35 -> #DIV/0! | AB35: =(D35-J35-R35)/V35 -> #DIV/0! | AC35: =(E35-K35-S35)/E35 -> #DIV/0! | AD35: =SUM(D35-H35)/D35 -> #DIV/0! | AG35: Estimated months claim | AH35: 0 | AK35: =SUM(W36-W35) -> 0 | AL35: =SUM(K36-K35) -> 0
C36: Week 4 | F36: =D36-E36 -> 0 | G36: =F36/D36 -> #DIV/0! | J36: =SUM(H36-R36) -> 0 | K36: =SUM(I36-S36) -> 0 | L36: =J36-K36 -> 0 | M36: =L36/J36 -> #DIV/0! | T36: =R36-S36 -> 0 | U36: =T36/R36 -> #DIV/0! | X36: =V36-W36 -> 0 | Y36: =X36/V36 -> #DIV/0! | AA36: =(E36-K36-S36)/W36 -> #DIV/0! | AB36: =(D36-J36-R36)/V36 -> #DIV/0! | AC36: =(E36-K36-S36)/E36 -> #DIV/0! | AD36: =SUM(D36-H36)/D36 -> #DIV/0! | AK36: =SUM(W37-W36) -> 0 | AL36: =SUM(K37-K36) -> 0
C37: Week 5 | F37: =D37-E37 -> 0 | G37: =F37/D37 -> #DIV/0! | J37: =SUM(H37-R37) -> 0 | K37: =SUM(I37-S37) -> 0 | L37: =J37-K37 -> 0 | M37: =L37/J37 -> #DIV/0! | T37: =R37-S37 -> 0 | U37: =T37/R37 -> #DIV/0! | X37: =V37-W37 -> 0 | Y37: =X37/V37 -> #DIV/0! | AA37: =(E37-K37-S37)/W37 -> #DIV/0! | AB37: =(D37-J37-R37)/V37 -> #DIV/0! | AC37: =(E37-K37-S37)/E37 -> #DIV/0! | AD37: =SUM(D37-H37)/D37 -> #DIV/0! | AK37: =SUM(AK32,AK33,AK34,AK35,AK36) -> -12.5 | AL37: =SUM(AL32,AL33,AL34,AL35,AL36) -> -171.84
